Workbook

Sheet Quaterly
A1: 2026 Roadmap - Jerel Smith
B2: Q1 2026 | C2: Q2 2026 | D2: Q3 2026 | E2: Q4 2026 | F2: Q1 2027 | G2: Q2 2027 | H2: Q3 2027 | I2: Q4 2027 | J2: Q1 2028 | K2: Q2 2028 | L2: Q3 2028 | M2: Q4 2028
A3: 1. B2B | E3: Freeze
A4: PMO-5000
A5: >CMS Lite | B5: Discovery | C5: Design + Dev | D5: Dev + Live
A6: >Sign Up | B6: Discovery | C6: Design + Dev | D6: Dev + Live
A7: >Internal Pages | B7: Discovery + Research | C7: Design + Dev | D7: Dev + Live
A8: B2B Hub Health Dashboard | D8: All
A9: The Studio
A10: Categories | B10: Discovery + Research | C10: Stakeholder Input | D10: Dev + Live
A11: >Landing Page | B11: Discovery + Research | C11: Design + Dev | D11: Dev + Live
A12: >Multi-Page | B12: Discovery + Research
A13: 2. Used
A14: Sell Used/Trade In
A15: >Sell Used Experience | B15: Discovery + Research | C15: Design + Dev | D15: Live
A16: >Trade In Experience | B16: Discovery + Research | C16: Design + Dev | D16: Live
A17: Trade In Emails | B17: Discovery | D17: …Live
A18: Used Hub Health Dashboard | C18: Discovery + Research | D18: …Live
A19: Condition Rating Scale
A20: >New Condition Rating Scale | B20: Discovery | C20: Design | D20: Dev + Live
A21: PDP - Group By Condition | B21: Discovery | C21: Design | D21: Dev + Live
A22: PLP - Roll Up By Condition
A23: Actual Used Images (Tim) | B23: Dev | C23: Operationalize | D23: Live
A24: 3. Legacy Find (Submitting to Dev - Not Owning Afterwards)
A25: Mega Menu | B25: Discovery + Research | C25: Design + Dev | D25: Live
A26: Roll Up SKUs | B26: Design + Grooming
A27: Nested Refinements | B27: Discovery + Design | C27: Design | D27: Dev + Live

Sheet Monthly
A2: Journey/Initiative | B2: Q1 | E2: Q2 | H2: Q3 | K2: Q4 | N2: Q1 | Q2: Q2 | T2: Q3 | W2: Q4
A3: Enterprise Platforms & Used | B3: January | C3: February | D3: March | E3: April | F3: May | G3: June | H3: July | I3: August | J3: September | K3: October | L3: November | M3: December | N3: January | O3: February | P3: March | Q3: April | R3: May | S3: June | T3: July | U3: August | V3: September | W3: October | X3: November | Y3: December
A4: 1. B2B | L4: Freeze
A5: PMO-5000
A6: >Weblogic-> Apeture/JSON Led | D6: Discovery + Research | E6: Design | G6: Dev | I6: Live
A7: >Sign Up | D7: Discovery + Research
A8: >Internal Pages | D8: Discovery + Research
A9: B2B Hub Health Dashboard | E9: Discovery | F9: Research | G9: Dev | H9: Live
A10: The Studio
A11: Categories | D11: Discovery + Research | E11: Design | F11: Dev
A12: >Landing Page | D12: Discovery | E12: Research | F12: Design | G12: Dev
A13: >Multi-Page | G13: Design | H13: Dev | I13: Dev | J13: Live
A14: EDU | B14: Design | F14: Dev | G14: Live
A15: 2. Used
A16: Sell Used/Trade In
A17: >Sell Used Experience | D17: Discovery + Research | E17: Design | F17: Design | G17: Dev | H17: Dev | I17: Live
A18: >Trade In Experience | D18: Discovery + Research | F18: Design | G18: Dev | H18: …Live
A19: Trade In Emails | D19: Discovery | E19: Design | F19: Dev | G19: Live
A20: Used Hub Health Dashboard | F20: Discovery + Research | G20: Dev | H20: Live
A21: Condition Rating Scale
A22: >New Condition Rating Scale | B22: Discovery | C22: Research | D22: Socialize | E22: Socialize | F22: Dev | G22: Live
A23: PDP - Group By Condition | E23: Design | F23: …Live
A24: PLP - Roll Up By Condition | H24: Discovery | I24: Research | J24: Live
A25: Actual Used Images (Tim) | E25: Design | F25: Dev | G25: Operationalize | H25: Operationalize | I25: Live
A26: 3. Legacy Find (Submitting to Dev - Not Owning Afterwards)
A27: Mega Menu | B27: Discovery | C27: Research | D27: Design | F27: …Live
A28: Nested Refinements | B28: Discovery | C28: Research | D28: Design | F28: Dev | G28: Live

Sheet Weekly
A1: Product | B1: Portfolio | C1: Theme #1 | D1: Theme #2 | E1: Title | F1: Jira | G1: Status | H1: 46125 | I1: 46132 | J1: 46139 | K1: 46146 | L1: 46153 | M1: 46160 | N1: 46167 | O1: 46174 | P1: 46181 | Q1: 46188 | R1: 46195 | S1: 46202 | T1: 46209 | U1: 46216 | V1: 46223 | W1: 46230 | X1: 46237 | Y1: 46244 | Z1: 46251 | AA1: 46258 | AB1: 46265 | AC1: 46272 | AD1: 46279 | AE1: 46286 | AF1: 46293 | AG1: 46300 | AH1: 46307 | AI1: 46314 | AJ1: 46321 | AK1: 46328 | AL1: 46335 | AM1: 46342 | AN1: 46349 | AO1: 46356 | AP1: 46363 | AQ1: 46370 | AR1: 46377 | AS1: 46384 | AT1: 46391 | AU1: 46398 | AV1: 46405 | AW1: 46412 | AX1: 46419 | AY1: 46426 | AZ1: 46433 | BA1: 46440 | BB1: 46447 | BC1: 46454 | BD1: 46461 | BE1: 46468 | BF1: 46475 | BG1: 46482 | BH1: 46489 | BI1: 46496 | BJ1: 46503 | BK1: 46510 | BL1: 46517 | BM1: 46524 | BN1: 46531 | BO1: 46538 | BP1: 46545 | BQ1: 46552 | BR1: 46559 | BS1: 46566 | BT1: 46573 | BU1: 46580 | BV1: 46587 | BW1: 46594 | BX1: 46601 | BY1: 46608 | BZ1: 46615 | CA1: 46622 | CB1: 46629 | CC1: 46636 | CD1: 46643 | CE1: 46650 | CF1: 46657 | CG1: 46664 | CH1: 46671 | CI1: 46678 | CJ1: 46685 | CK1: 46692 | CL1: 46699 | CM1: 46706 | CN1: 46713 | CO1: 46720 | CP1: 46727 | CQ1: 46734 | CR1: 46741 | CS1: 46748 | CT1: 46755
A2: Jerel Smith | B2: Used | C2: Improve Buy Used Customer Experience | D2: Improve Trade In User Flow | E2: New Condition Rating Scale | F2: BHUX-33510 | G2: 00. Parking Lot | O2: Leo | P2: Leo | Q2: Leo
A3: Jerel Smith | B3: B2B | C3: Increase B2B Acquisition | E3: B2B Hub - Logged In B2B Experience | F3: BHP-6901 | G3: 00. Parking Lot | P3: Jaye | AG3: Jaye | AH3: Jaye | AI3: Jaye | AJ3: Jaye
A4: Jerel Smith | B4: B2B | C4: Improve The Studio B&H Customer Experience | E4: B2B - The Studio Categories | F4: BHUX-33434 | G4: 01. Prod Discovery | I4: Hilli | K4: Hilli | P4: Hilli | AB4: Hilli | AC4: Hilli | AD4: Hilli
A5: Jerel Smith | B5: B2B | C5: Increase The Studio B&H Awareness | E5: The Studio - Stand Alone Website | G5: 01. Prod Discovery | AC5: Sumit | AD5: Sumit | AE5: Sumit
A6: Jerel Smith | B6: B2B | E6: Homepage Header: B2B | F6: BHP-7274 | G6: 01. Prod Discovery
B7: Used | C7: Increase Trade In Awareness | E7: Decouple Sell Used from Used Hub | F7: BHP-7431 | G7: 01. Prod Discovery
A8: Jerel Smith | B8: Used | C8: Improve Trade In User Flow | E8: Sell Used Purchase Look Up | F8: BHP-7236 | G8: 02. UX Req | AA8: John | AB8: John | AC8: John
A9: Jerel Smith | B9: Used | C9: Increase Trade In Awareness | E9: Used Activity Notification | F9: BHP-7237 | G9: 02. UX Req | AD9: John | AE9: John | AF9: John
A10: Jerel Smith | B10: B2B | C10: Improve The Studio B&H Customer Experience | E10: The Studio - Enhanced Landing Page | F10: BHP-6444 | G10: 02. UX Req | AC10: Sumit | AD10: Sumit | AE10: Sumit
B11: B2B | C11: Increase B2B Acquisition | E11: FDOT Hero Image | F11: BHP-7394 | G11: 02. UX Req | AA11: Nachman
A12: Jerel Smith | B12: Used | C12: Increase Buy Used Awareness | E12: Used Hub - Just Added Component | F12: BHP-7229 | G12: 02. UX Req | Y12: John | AC12: John | AD12: John
A13: Jerel Smith | B13: B2B | C13: Increase The Studio B&H Awareness | E13: The Studio - Category Hybrid Page | F13: BHP-7301 | G13: 02. UX Req | Y13: Sumit | AA13: Sumit | AB13: Sumit
A14: Jerel Smith | B14: Used | C14: Increase Buy Used Awareness | E14: Used Just Added Page | F14: BHP-7230 | G14: 02. UX Req | M14: Nachman | N14: Nachman | AG14: Nachman | AH14: Nachman
A15: Jerel Smith | B15: Used | C15: Increase Trade In Awareness | E15: Increase Awareness of Trade In Offers - Best Buy Inspiration/Competitive Effort | F15: BHP-6827 | G15: 02. UX Req
A16: Jerel Smith | B16: Used | C16: Increase Buy Used Awareness | E16: Out of stock Alerts for used products | F16: BHUX-35020 | G16: 03. UX Discovery | X16: Leo | Y16: Leo | Z16: Leo | AA16: Leo
A17: Jerel Smith | B17: B2B | C17: Increase The Studio B&H Awareness | E17: The Studio - B&H Awareness on High Ticket Items | F17: BHUX-35304 | G17: 03. UX Discovery | Z17: Leo | AA17: Leo | AB17: Leo | AC17: Leo
A18: Jerel Smith | B18: Used | C18: Increase Buy Used Awareness | D18: Improve Discovery | E18: Add New | Used tab to all listing pages and search results pages | F18: BHUX-35303 | G18: 03. UX Discovery | AA18: Sumit | AB18: Sumit | AC18: Sumit | AD18: Sumit
A19: Jerel Smith | B19: Find | C19: Improve Discovery | E19: Highlighted Refinements Enhancement | F19: BHUX-35302 | G19: 04. UX Design | AA19: Sumit | AB19: Sumit | AC19: Sumit | AD19: Sumit
A20: Jerel Smith | B20: Used | C20: Improve Trade In User Flow | E20: Trade In Email - Comprehensive Refresh Discovery | F20: BHUX-34772 | G20: 04. UX Design | U20: John | V20: John | W20: John | X20: John
A21: Jerel Smith | B21: Used | C21: Improve Trade In User Flow | E21: Used - Sell Used Experience | F21: BHUX-33009 | G21: 04. UX Design | I21: John | J21: John | K21: John | L21: John | M21: John | N21: John | O21: John | P21: John | Q21: John | R21: John | S21: John | T21: John | U21: John | V21: John | W21: John | X21: John | Y21: John | Z21: John | AA21: John | AB21: John | AC21: John | AD21: John | AE21: John | AF21: John
A22: Jerel Smith | B22: Used | C22: Increase Buy Used Awareness | E22: Add 'shop by popular brands' section to Used Homepage | F22: BHUX-34844 | G22: 04. UX Design | V22: John | W22: John | X22: John | Y22: John | Z22: John | AA22: John
A23: Jerel Smith | B23: Used | C23: Increase Buy Used Awareness | E23: Shop By Popular Brand' Listing Pages Discovery | F23: BHUX-34845 | G23: 04. UX Design | W23: Sumit | X23: Sumit | Y23: Sumit | Z23: Sumit | AA23: Sumit
A24: Jerel Smith | B24: Used | C24: Increase Buy Used Awareness | E24: My Account > Trade In Awareness | F24: BHUX-35010 | G24: 04. UX Design | Y24: Mehek | Z24: Mehek | AA24: Mehek
A25: Jerel Smith | B25: B2B/Used | C25: Increase Trade In Awareness | D25: Increase B2B Acquisition | E25: B2B & Used Visibility in the Nav | F25: BHUX-34378 | G25: 04. UX Design | O25: Sumit | P25: Sumit | Q25: Sumit | R25: Sumit | S25: Sumit | T25: Sumit | U25: Sumit | V25: Sumit | W25: Sumit | X25: Sumit | Y25: Sumit | Z25: Sumit | AA25: Sumit | AB25: Sumit | AC25: Sumit | AD25: Sumit | AE25: Sumit | AF25: Sumit
A26: Jerel Smith | B26: Used | C26: Improve Trade In User Flow | E26: Sell Used User Flow Design Validation | F26: BHUR-133 | G26: 04A. Research - Design Validation | T26: Hanna | U26: Hanna | V26: Hanna | W26: Hanna | X26: Hanna | Y26: Hanna | Z26: Hanna | AA26: Hanna
A27: Jerel Smith | B27: Used | C27: Improve Trade In User Flow | E27: Used Status Email Update | F27: BHUX-34723 | G27: 06. Architecture | U27: John
A28: Jerel Smith | B28: Used | C28: Increase Trade In Awareness | E28: PDP Purchased in 20XX, Trade In Value is $YYY.YY | F28: BHUX-35309 | G28: 06. Architecture | Z28: Alice
A29: Jerel Smith | B29: Find | C29: Improve Discovery | E29: Mega Menu | F29: BHUX-29580 | G29: 07. Grooming | J29: Laura | K29: Laura | O29: Sumit
A30: Jerel Smith | B30: B2B | C30: Increase B2B Acquisition | E30: School Safety Landing Page | F30: BHUX-34377 | G30: 07. Grooming | Q30: Hilli | R30: Hilli | S30: Hilli | T30: Hilli | U30: Hilli | V30: Hilli | W30: Hilli | X30: Hilli | Y30: Hilli
A31: Jerel Smith | B31: B2B | C31: Increase B2B Acquisition | E31: B2B Hub Landing Page - redesign | F31: BHUX-26541 | G31: 07. Grooming | H31: Jaye | I31: Jaye | J31: Jaye | K31: Jaye | L31: Jaye
A32: Jerel Smith | B32: B2B | C32: Increase B2B Acquisition | E32: B2B Hub - Revisit Signup Flow | F32: BHUX-31874 | G32: 07. Grooming | H32: Jaye | I32: Jaye | J32: Jaye | K32: Jaye | L32: Jaye | M32: Jaye | N32: Jaye
A33: Jerel Smith | B33: B2B | C33: Increase B2B Acquisition | E33: B2B Hub Redesign - Internal Pages | F33: BHUX-32257 | G33: 07. Grooming | I33: Jaye | J33: Jaye | K33: Jaye | L33: Jaye
A34: Jerel Smith | B34: Used | C34: Improve Buy Used Customer Experience | D34: Improve Trade In User Flow | E34: New Condition Rating Scale (Intermediate Step) | F34: BHJ-121278 | G34: 07. Grooming
A35: Jerel Smith | B35: Find | C35: Improve Discovery | E35: Nested Refinements | F35: BHUX-32621 | G35: 08. Ready for Dev
A36: Jerel Smith | B36: Find | C36: Improve Discovery | E36: Sunset Modals for Drawers | F36: BHUX-32543 | G36: 09. In Dev
A37: Jerel Smith | B37: Used | C37: Improve Trade In User Flow | E37: Trade In Discrepancy Email Refresh (Copy Only) | G37: 09. In Dev | U37: John | V37: John
A38: Jerel Smith | B38: Used | C38: Increase Buy Used Awareness | E38: Condition Grouping | F38: BHUX-33519 | G38: 10. QA | J38: Leo | K38: Leo
B39: Find | C39: Improve Discovery | E39: Sliders | F39: BHUX-17615 | G39: 13. Live
B40: Find | C40: Improve Discovery | E40: Refinement - Select All/Deselect All | F40: BHUX-23755 | G40: 13. Live
...

Sheet Model (Don't Touch)
B3: Reduce impediments and increase transparency/trust across internal teams by answering the following questions:
B4: Who wants this?
B5: Why are we doing this?
B6: What's the bigger picture?
B7: How do we know if it worked?
B8: Where will the customer encounter this experience?
B37: Portfolios | C37: Who are the primary stakeholders?
B38: Theme | C38: What are the ongoing high level efforts that create a positive impact on customer experience and revenue?
B39: Roadmap | C39: What is the sequence of deliverables and why?
B40: Metrics | C40: Through which lens do we judge performance/success?
B41: Components | C41: What elements are involved in this theme/request?
B42: GA4 | C42: Is the Component tagged? If so, is it tagged in a meaningful way?

Sheet Initiative Tracker
A4: Title | B4: Ticket | C4: Status | D4: Portfolio | E4: Component | F4: Tech | G4: Start Sprint | H4: End Sprint | I4: Notes
A5: Post Hub | B5: BHP-6901 | C5: 99. Parking Lot | D5: B2B | E5: B2B Hub | F5: BHJ | G5: Oct 2026 | H5: Jan 2027 | I5: Deprioritized by Ariel until visibility in the Nav is addressed
A6: School Safety Landing Page | B6: BHP-5830 | C6: 2. Design | D6: B2B | E6: B2B Hub Plus | F6: BHJ | G6: Sep 2026 | H6: Sep 2026 | I6: https://www.bhphotovideo.com/c/browse/school-safety/ci/64314 has been created to point the categories on the landing page towards
A7: EDU Homepage | B7: BHP-3583 | C7: 4. Dev | D7: B2B | E7: EDU | F7: BHJ | G7: Aug 2026 | H7: Aug 2026
A8: B2B Hub | B8: PMO-5000 | C8: 7. Live | D8: B2B | E8: B2B Hub | F8: BHJ
A9: B2B The Studio Categories | B9: BHP-6446 | C9: 99. Parking Lot | D9: B2B | E9: B2B Hub | F9: BHJ | I9: Impeded by stakehodler availability
A10: Mega Menu | B10: BHP-6955 | C10: 3. Architecture | D10: Merchandising | E10: Navigation | F10: BHJ, BHIA, BIDW | G10: Aug 2026 | H10: Oct 2026 | I10: Four technical ideation meetings booked, two complete, Progress being made with tech reqs
A11: Highlighted Refinements | C11: 7. Live | D11: Merchandising | E11: PLP/Search | F11: BHJ, Search, BHIA | G11: May | H11: Jul 2026 | I11: Operationalizing with Shalom Oster & Daniel Ballas, should be live late June, currently in Pull Request
A12: Sell Used | B12: BHP-6434 | C12: 2B. Research | D12: Used Operations | E12: Sell Used | F12: UNIX, BHJ, SEARCH | G12: Sep 2026 | H12: Jan 2027 | I12: Research transitioned from Birdie to Hanna, pausing for ramp up
A13: New Condition Rating Scale | B13: BHP-4771 | C13: 99. Parking Lot | D13: Used Operations | E13: PLP/PDP | F13: UNIX, BHJ | G13: Aug 2026 | H13: Aug 2026 | I13: Due to trepidation by the stakeholder, let's freeze this initiative and pivot to a slow release: remove +9, Demo and add short and long term descriptions via DBA requests (no BHJ)
A14: Group by Conditon | B14: BHP-4518 | C14: 4. Dev | D14: Used Operations | E14: PLP/PDP | F14: BHJ | G14: Aug 2026 | H14: Aug 2026 | I14: Met with architecture, requirements confirmed, moving forward with dev
A15: Actual Used Images | C15: 5. Implementation | D15: Used Operations | E15: PDP/ Images | F15: BHJ, BHIA | G15: Mar 2026 | H15: Jun 2026 | I15: Reached out to Isaac to make the Ortery Purchase
A16: Trade In Emails - Comprehensive Revamp | B16: BHP-6391 | C16: 1. UX Discovery | D16: Used Operations | E16: Trade In Email | F16: UNIX | G16: Aug 2026 | H16: Aug 2026
A17: Used Search Terms | B17: BIDW-98341 | C17: 4. Dev | D17: Used Operations | E17: Sell Used | F17: BIDW | G17: Aug 2026 | H17: Aug 2026 | I17: Research the search terms used over the last 6 months https://jira.bnh.com/browse/BIDW-98341
A18: Nested Refinements | B18: BHP-2802 | C18: 4. Dev | D18: Web Experience | E18: PLP/Search | F18: BHJ, BHIA, SEARCH | G18: Sep 2026 | H18: Nov | I18: Multiple Prerequisites and dependencies: BHIA, BHJs
A19: My Gear Release 2 | B19: BHP-3683 | C19: 4. Dev | D19: Web Experience | E19: My Gear | F19: BHJ, BHIA, SEARCH
A20: Sunset Deal Zone | C20: 7. Live | D20: Web Experience | E20: Navigation | F20: BHJ | G20: Jun 2026 | H20: Aug 2026 | I20: Almost complete, need Permalink and nav jiras live
A21: View All Category Landing Page | C21: 7. Live | D21: Web Experience | E21: Category Landing Page | F21: BHJ, BHIA | H21: Jul 2026 | I21: Approved UAT; operationalizing with nav arcs
A22: Roll Up SKUs | B22: BHP-11 | C22: 99. Parking Lot | D22: Web Experience | E22: PLP/Search | F22: BHJ, BHIA, SEARCH
A23: The Studio - Stand Alone Website | D23: The Studio - B2B | E23: The Studio | F23: BHJ | G23: Sep 2026 | H23: Mar 2027
A24: The Studio - Enhanced Landing Page | B24: BHP-6444 | C24: 0. Discovery | D24: The Studio - B2B | E24: B2B Hub | F24: BHJ | G24: Oct 2026 | H24: Jan 2027
A25: The Studio - Category Hybrid Page | B25: BHP-7301 | C25: 1. UX Discovery | D25: The Studio - B2B | E25: PLP/Search | F25: BHJ | G25: Aug 2026 | H25: Oct 2026
A26: The Studio - B&H Awareness on High Ticket Items | B26: BHP-7239 | C26: 2. Design | D26: The Studio - B2B | E26: PDP | F26: BHJ
A27: Sell Used Purchase Look Up | B27: BHP-7236 | C27: 1. UX Discovery | D27: Used Operations | E27: Sell Used | F27: BHJ, UNIX
A28: PDP Purchased in 20XX, Trade In Value is $YYY.YY | B28: BHP-7228 | D28: Used Operations | E28: PDP | F28: BHJ, BHIA
A29: Used Just Added Page | B29: BHP-7230 | D29: Used Operations | F29: BHJ
A30: Used Activity Notification | B30: BHP-7237 | C30: 0. Discovery | D30: Used Operations | E30: Used Hub | F30: BHJ, UNIX
A31: Highlighted Refinements Enhancement | B31: BHP-7226 | D31: Web Experience | E31: PLP/Search | F31: BHJ
A32: Homepage Header: B2B | B32: BHP-7274 | D32: B2B | F32: BHJ
A33: Increase Awareness of Trade In Offers - Best Buy Inspiration/Competitive Effort | B33: BHP-6827 | D33: Used Operations | E33: PLP/Search | F33: BHJ

Sheet Obsolete
A3: Product | B3: Portfolio | C3: Theme | D3: Title | E3: Jira | F3: Status
A4: Brendan Bagley | D4: Tax & Net 30 Terms On CompanyID | E4: BHUX-33524 | F4: 06. Architecutre
A5: Brendan Bagley | B5: B2B | D5: B2B Updated Expired Tax Exemption | E5: BHUX-33186 | F5: 05. Business Review
A6: Brendan Bagley | B6: Site Support | D6: Enable Editable Email Addresses in the ShipTo | E6: BHUX-34079 | F6: 05. Business Review
A7: Brendan Bagley | B7: B2B Portals | D7: Identify Users via the PunchoutSetupRequest and Give them Limited User-Based Features | E7: BHUX-33409 | F7: 05. Business Review
A8: Brendan Bagley | B8: B2B | D8: Update Punch out Cart to match B2B/B2B cart/checkout | E8: BHUX-33526 | F8: 05. Business Review
A9: Brendan Bagley | B9: B2B | D9: Gradus equivalents in B2B Quotes | E9: BHUX-33797 | F9: Closed as later

Sheet Control (Don’t Touch)
A3: Portfolio | B3: Status | E3: Theme | F3: Description | G3: Measure Adoption | H3: Measure Impact | K3: Event Taxonomy
A4: B2B | B4: 00. Parking Lot | E4: Improve Discovery | F4: OG Find initaitives that Jerel still owns
A5: Used | B5: 01A. Research - Foundational | E5: Increase Trade In Awareness | F5: Surface trade-in as a clear, relevant option at high-intent moments, Order History, PDPs, post-purchase, so customers who own eligible gear know they can trade it in. | G5: Trade-in CTA Impressions (Order History/PDP), CTA Click through rate, % of eligible sessions exposed to CTA | H5: New to trade in quote starts, Quote start rate among CTA exposed users, Assisted trade-in revenue (CTA attributed) | K5: listing_page_clicks
A6: Find | B6: 01. Prod Discovery | E6: Improve Trade In User Flow | F6: Reduce friction in the sell/trade-in submission flow: search, quote, shipping/drop-off, to raise completion and quote-to-conversion rates. | G6: % started quotes completed, Time to quote (median), Post-acceptance ststus engagement rate | H6: Quote-to-accepted-offer rate, Drop-off rate by flow step, sell-flow CSAT (isolated), Support contact rate per quote, Payout cycle time (accepted>paid) | K6: category_page_clicks
B7: 02. UX Req | E7: Increase Trade In Reactivation | F7: Re-engage past customers with unused eligible gear via triggered emails tied to purchase timing and inventory demand signals. | G7: Reactivation email open rate, reactivation email CTR, quote starts attributed to email | H7: Reactivated quote to completion rate, revenue from reactivated sellers, days since last purchase > trade in (trend) | K7: detail_page_clicks
B8: 03. UX Discovery | E8: Increase Buy Used Awareness | F8: Grow discovery of the Used Hub and used inventory through SEO, brand listing pages, and internal linking so more shoppers know B&H sells used gear. | G8: Organic sessions to Used Hub/brand pages, Search impressions & CTR (used pages), Internal link CTR (New>used cross links), Cross-sell CTA impressions (used alt. on New PDP) | H8: New-to-used buyer sessions, Used PDP views per session, Used share to total category traffic, cross sell attributed used PDP views/purchases | K8: header_clicks
B9: 04. UX Design | E9: Improve Buy Used Customer Experience | F9: Make used PDPs and listing pages easier to evaluate, increase condition clarity, provide product photos, and filtering, so shoppers can confidently purchase used gear | G9: PLP filter usage rate, used pdp engagement rate (photo/spec expansion), order status page engagement rate | H9: Used PDP-to-cart rate, Used cart-to-purchase rate, Post-Purchase CSAT (isolated) | K9: mega_menu_clicks
B10: 04A. Research - Design Validation | E10: Increase Buy Used Reactivation | F10: Win back past buyers with relevant used-inventory alerts and win-back offers matched to their purchase history | G10: Win Back email open rate, win-back email CTR, Browse to used PDP rate from email | H10: Repeat used-purchase rate, Revenue from reactivated buyers, Time-since-last-purchase > repurchase (trend) | K10: typeahead_suggestion_clicks
B11: 05. Business Review | E11: Increase B2B Acquisition | K11: footer_clicks
B12: 06. Architecture | E12: Increase The Studio B&H Awareness | K12: home_page_clicks
B13: 07. Grooming | E13: Improve The Studio B&H Customer Experience | K13: nav_drawer_clicks
B14: 08. Ready for Dev | E14: Increase Trust & Condition Transparency | F14: Cross-cutting theme covering whether customers believe the grading/condition information is accurate and complete, ties directly to condition rating scale and PDP condition grouping work, and carries COO-level visibility | K14: cart_page_clicks
B15: 09. In Dev | E15: Improve Search & Findability | F15: Cross-cutting theme spanning sell-side item search (finding what you own to quote it) and buy-side discovery (finding used inventory to purchase). Flagged as the single highest-priority friction point across VoC research on both sides. | K15: checkout_page_clicks
B16: 10. QA | K16: checkout_impression
B17: 11. UAT | K17: login_layer_clicks
B18: 12. Release | K18: profile_menu_clicks
B19: 13. Live | K19: my_account_clicks
K20: order_history_detail_clicks
K21: modify_order_page_clicks
K22: static_pages_clicks
K23: gift_ideas_clicks
K24: leasing_page_clicks
K25: payboo_page_clicks
K26: payboo_sdk_clicks

Sheet Metrics (Don't Touch)
A2: Portfolio | B2: Theme | C2: Metric | D2: Description | E2: Calculation | F2: Why it Matters | G2: Type | H2: Source | I2: Components | K2: Available
A3: Used | B3: Increase Trade In Awareness | C3: Trade-in CTA Impressions (Order History/PDP) | D3: The number of times a trade-in call-to-action (button, banner, or module) was actually rendered and seen through out the site. | E3: Count of CTA element view events, deduped per session. | F3: Impressions are the ceiling on everything downstream. If the CTA isn't being shown, nothing else in this theme can move. | G3: Adoption | H3: GA4 | I3: Homepage Banner, PDP, PLP, My Account
A4: Used | B4: Increase Trade In Awareness | C4: CTA Click through rate | D4: Of the sessions where the CTA was shown, the share that clicked it. | E4: CTA clicks ÷ CTA impressions. | F4: Tells you whether the CTA itself (copy, placement, design) is compelling, independent of how often it's shown. | G4: Adoption | H4: GA4 | I4: Homepage Banner, PDP, PLP, My Account
A5: Used | B5: Increase Trade In Awareness | C5: % of eligible sessions exposed to CTA | D5: Of all sessions where a customer has an eligible order/product (i.e. the CTA logic should have fired), the share that actually saw it. | E5: Sessions with CTA impression ÷ sessions meeting eligibility criteria. | F5: Separates "the CTA doesn't work well" from "the CTA isn't reaching who it should," a targeting/eligibility-logic health check. | G5: Adoption | H5: GA4 | I5: Homepage Banner, PDP, PLP, My Account
A6: Used | B6: Increase Trade In Awareness | C6: New to trade in quote starts | D6: Quote submissions started by customers who have never started a trade-in quote before. | E6: Count of first-ever quote-start events, matched against customer history in the Quote system. | F6: Isolates net-new acquisition from repeat sellers, so the awareness theme is measured on bringing in new sellers, not just repeat activity. | G6: Impact | H6: Quote system | I6: Sell Used Search, My Account Trade In Module, Trade In Page
A7: Used | B7: Increase Trade In Awareness | C7: Quote start rate among CTA exposed users | D7: Of customers exposed to the trade-in CTA, the share who went on to start a quote (not necessarily via the CTA itself, any path). | E7: Quote starts among CTA-exposed users ÷ CTA-exposed users. | F7: The real end-to-end conversion signal for the awareness surface, closer to business outcome than CTR alone. | G7: Impact | H7: GA4 + Quote system
A8: Used | B8: Increase Trade In Awareness | C8: Assisted trade-in revenue (CTA attributed) | D8: Dollar value of inventory acquired through trade-ins where the CTA played a role in the customer's path, even if not the last touch before quoting. | E8: Sum of accepted-quote $ value for quotes with a CTA touchpoint anywhere in the session/journey. | F8: Awareness surfaces often assist rather than directly convert. Last-touch attribution alone would undercount their value. | G8: Impact | H8: GA4 + Finance | I8: Homepage Banner, PDP, PLP, My Account
A9: Used | B9: Increase Trade In Awareness | C9: Cross-sell CTA impressions (New PDP / brand pages) | D9: Impressions of a trade-in prompt shown while a customer is browsing new (not used) gear, e.g. "have an old one? trade it in." | E9: Count of CTA view events on New PDP / brand pages, deduped per session. | F9: This is a different acquisition channel than Order History awareness. It reaches people who haven't bought from B&H recently. | G9: Adoption | H9: GA4 | I9: New PDP Trade In Your Gear
A10: Used | B10: Increase Trade In Awareness | C10: Cross-sell-attributed quote starts | D10: Quote starts that can be traced back to the cross-sell CTA shown on New PDP/brand pages. | E10: Quote-start events with a cross-sell CTA touchpoint in the preceding session(s). | F10: Tests whether pulling people out of the New funnel into trade-in actually works as an acquisition channel, distinct from Order History awareness. | G10: Impact | H10: GA4 + Quote system | I10: New PDP Trade In Your Gear
A11: Used | B11: Improve Trade In User Flow | C11: % started quotes completed | D11: Of all quote flows a customer started (searched/selected at least one item), the share that reached a final submitted quote. | E11: Completed quote submissions ÷ quote flows started. | F11: The single clearest signal of overall flow friction, the headline number for this theme. | G11: Adoption | H11: Quote system
A12: Used | B12: Improve Trade In User Flow | C12: Time to quote (median) | D12: How long it takes a customer to go from starting the flow to receiving a quote value, at the midpoint of the distribution. | E12: Median of (quote-received timestamp − flow-start timestamp) across completed quotes. | F12: Slow quoting is a known drop-off driver; median avoids a few slow outliers skewing the picture. | G12: Adoption | H12: Quote system
A13: Used | B13: Improve Trade In User Flow | C13: Post-acceptance status engagement rate | D13: Of customers who accepted a quote, the share who opened a status update (email or status page) about shipping/payout progress. | E13: Unique opens/views of post-acceptance status content ÷ accepted quotes. | F13: Checks whether status communications meant to reduce post-acceptance uncertainty are actually being read. | G13: Adoption | H13: ESP + GA4 | I13: Email Shipping Email, Trade in Quote Notification
A14: Used | B14: Improve Trade In User Flow | C14: Quote-to-accepted-offer rate | D14: Of quotes issued to customers, the share the customer actually accepted. | E14: Accepted quotes ÷ quotes issued. | F14: Distinguishes "the flow works but the price is wrong" (low acceptance) from "the flow itself is broken" (low completion, above). | G14: Impact | H14: Quote system | I14: Email CTA
A15: Used | B15: Improve Trade In User Flow | C15: Drop-off rate by flow step | D15: The percentage of customers who exit at each individual step of the sell flow (e.g. item search, condition selection, shipping info). | E15: (Users entering step − users entering next step) ÷ users entering step, per step. | F15: Pinpoints exactly where in the flow friction is worst, so fixes can be targeted rather than guessed at. | G15: Impact | H15: GA4 | I15: Sell Used Search Box, Sell Used Type Ahead, Sell Used Listing Page, Sell Used Detail Page, Sell Used Review Page
A16: Used | B16: Improve Trade In User Flow | C16: Sell-flow CSAT (isolated) | D16: Customer satisfaction score from a survey specifically scoped to the sell/trade-in flow, kept separate from site-wide CSAT. | E16: Medallia CSAT question average/top-box %, filtered to sell-flow survey instance. | F16: Site-wide CSAT would dilute sell-flow-specific pain; isolating it makes the score actionable for this theme. | G16: Impact | H16: Medallia
A17: Used | B17: Improve Trade In User Flow | C17: Support contact rate per quote | D17: How often a customer contacts support (chat, phone, email) in connection with a given quote. | E17: Support tickets tagged to a quote ID ÷ total quotes. | F17: A proxy for hidden friction. High contact rates mean customers can't self-serve through confusion or problems in the flow. | G17: Impact | H17: Support / CRM
A18: Used | B18: Improve Trade In User Flow | C18: Payout cycle time (accepted>paid) | D18: Time elapsed from a customer accepting a quote to the payout actually being issued. | E18: Payout-issued timestamp − quote-accepted timestamp, median across accepted quotes. | F18: Payout speed is a top driver of seller trust and repeat behavior. | G18: Impact | H18: Finance + WMS
A19: Used | B19: Increase Trade In Reactivation | C19: Reactivation email open rate | D19: Share of sent trade-in reactivation emails that were opened. | E19: Unique opens ÷ emails delivered. | F19: The first checkpoint. If subject lines/targeting aren't landing, nothing downstream can work. | G19: Adoption | H19: ESP | I19: Trade in email
A20: Used | B20: Increase Trade In Reactivation | C20: Reactivation email CTR | D20: Share of sent reactivation emails that resulted in a click. | E20: Unique clicks ÷ emails delivered (or ÷ opens, for click-to-open rate). | F20: Tests whether the email content/offer itself is compelling once someone opens it. | G20: Adoption | H20: ESP | I20: Used Email, Used Email CTA
A21: Used | B21: Increase Trade In Reactivation | C21: Quote starts attributed to email | D21: Quote flows started by a customer within a defined attribution window after clicking a reactivation email. | E21: Quote-start events with a reactivation-email click in the prior N days (window TBD). | F21: Bridges "they clicked" to "they actually engaged with the trade-in flow." | G21: Adoption | H21: ESP + Quote system
A22: Used | B22: Increase Trade In Reactivation | C22: Reactivated quote to completion rate | D22: Of quotes started via reactivation email, the share that reach a completed/accepted quote. | E22: Completed quotes (email-attributed) ÷ quote starts (email-attributed). | F22: Checks whether reactivated sellers behave differently than new/organic sellers once in the flow. | G22: Impact | H22: Quote system
A23: Used | B23: Increase Trade In Reactivation | C23: Revenue from reactivated sellers | D23: Total $ value of inventory acquired from customers reactivated via this campaign. | E23: Sum of accepted-quote $ value for email-attributed reactivated sellers. | F23: The bottom-line business case for continuing to invest in reactivation campaigns. | G23: Impact | H23: Finance + Quote system
A24: Used | B24: Increase Trade In Reactivation | C24: Days since last purchase > trade in (trend) | D24: How long, on average, it takes a past purchaser to trade in gear after their last purchase, tracked as a trend over time. | E24: Trade-in date − most recent prior purchase date, averaged/median across reactivated sellers, tracked quarter over quarter. | F24: If this trend is shortening, it suggests the timing/targeting logic behind the campaign triggers is improving. | G24: Impact | H24: CRM
A25: Used | B25: Increase Buy Used Awareness | C25: Organic sessions to Used Hub/brand pages | D25: Sessions landing on Used Hub or used brand listing pages via unpaid search. | E25: GA4 sessions filtered to organic-search channel + landing page = Used Hub/brand pages. | F25: The core SEO health signal for the whole awareness theme, a direct read on whether the hybrid listing-page architecture is working. | G25: Adoption | H25: GA4 | I25: Used Hub, Used Brand Listing Page
A26: Used | B26: Increase Buy Used Awareness | C26: Search impressions & CTR (used pages) | D26: How often used pages show up in Google search results, and what share of those impressions turn into a click. | E26: Pulled directly from Google Search Console, filtered to used-page URLs. | F26: A leading indicator ahead of organic sessions, showing whether pages are being surfaced/ranked before traffic shows up. | G26: Adoption | H26: Google Search Console
A27: Used | B27: Increase Buy Used Awareness | C27: Internal link CTR (New>used cross links) | D27: Click-through rate on links that point from new-gear pages (e.g. brand pages owned by Sammy) into used inventory. | E27: Clicks on internal used-links ÷ impressions of those links. | F27: Internal linking is both an SEO signal and a direct discovery channel. This checks it's actually being used. | G27: Adoption | H27: GA4 | I27: New PDP, Used PDP
A28: Used | B28: Increase Buy Used Awareness | C28: Cross-sell CTA impressions (used alt. on New PDP) | D28: Impressions of a "used alternative available" prompt shown on a new-gear product page. | E28: Count of CTA view events on New PDPs, deduped per session. | F28: Catches price-sensitive shoppers already in a New PDP session, a distinct discovery channel from search/SEO. | G28: Adoption | H28: GA4
A29: Used | B29: Increase Buy Used Awareness | C29: New-to-used buyer sessions | D29: Sessions from customers who have never viewed or purchased a used product before. | E29: Sessions with a used PDP view, matched against customer history for first-time-used flag. | F29: Awareness should be judged on growing the used buyer base, not just increasing traffic from existing used shoppers. | G29: Impact | H29: GA4
A30: Used | B30: Increase Buy Used Awareness | C30: Used PDP views per session | D30: Average number of used product pages viewed within a single session. | E30: Total used PDP views ÷ total sessions with at least one used PDP view. | F30: A rough proxy for browsing depth/engagement once a shopper lands in the used ecosystem. | G30: Impact | H30: GA4
A31: Used | B31: Increase Buy Used Awareness | C31: Used share to total category traffic | D31: Used PDP/category traffic as a percentage of all traffic (new + used) to the same product categories. | E31: Used-category sessions ÷ (used + new-category sessions), by category. | F31: Shows whether used is growing its footprint relative to new, not just growing alongside site-wide traffic. | G31: Impact | H31: GA4 | I31: Used PDP, Used Category Landing Page, Used Category Listing Page, New PDP, New Category Landing Page, New Category Listing Page
A32: Used | B32: Increase Buy Used Awareness | C32: Cross sell attributed used PDP views/purchases | D32: Used PDP views or purchases that followed a cross-sell CTA click on a New PDP. | E32: Used PDP views/purchases with a cross-sell CTA touchpoint in the preceding session(s). | F32: Validates whether the New→Used cross-sell mechanism is actually converting, not just generating impressions. | G32: Impact | H32: GA4 | I32: Used PDP, Used Check Out?, New Product Card Used From
A33: Used | B33: Improve Buy Used Customer Experience | C33: PLP filter usage rate | D33: Share of used listing-page sessions where a customer applies at least one filter (price, brand, condition, etc.). | E33: Sessions with a filter-applied event ÷ used PLP sessions. | F33: Low usage can mean filters aren't helpful/discoverable; high usage with low downstream conversion can flag a filter/inventory mismatch. | G33: Adoption | H33: GA4 | I33: Used PLP, Used SRP, Used Filter
A34: Used | B34: Improve Buy Used Customer Experience | C34: Used PDP engagement rate (photo/spec expansion) | D34: Share of used PDP sessions where a customer interacts with photos (zoom/gallery) or expands spec/condition detail sections. | E34: Sessions with photo-interaction or spec-expansion events ÷ used PDP sessions. | F34: A proxy for how much evaluation effort shoppers are putting in, tied directly to the photography and condition-clarity investments underway. | G34: Adoption | H34: GA4
A35: Used | B35: Improve Buy Used Customer Experience | C35: Order status page engagement rate | D35: Share of used-order customers who view their order status page after purchase. | E35: Unique order-status-page views ÷ used orders placed. | F35: Post-purchase visibility affects trust and support load, mirroring the post-acceptance metric on the sell side. | G35: Adoption | H35: GA4 | I35: My Orders
A36: Used | B36: Improve Buy Used Customer Experience | C36: Used PDP-to-cart rate | D36: Share of used PDP sessions that result in an add-to-cart. | E36: Add-to-cart events on used PDPs ÷ used PDP sessions. | F36: The core "does the PDP convince the shopper" metric, most sensitive to condition clarity and photography quality. | G36: Impact | H36: GA4 | I36: Used PDP, Used PDP CTA
A37: Used | B37: Improve Buy Used Customer Experience | C37: Used cart-to-purchase rate | D37: Share of used add-to-cart events that result in a completed purchase. | E37: Used purchases ÷ used add-to-cart events. | F37: Isolates checkout-stage friction from PDP-stage persuasion, since the two have different fixes. | G37: Impact | H37: GA4 | I37: Used PDP, Used PDP CTA, Used PLP, Used PLP CTA
A38: Used | B38: Improve Buy Used Customer Experience | C38: Post-Purchase CSAT (isolated) | D38: Customer satisfaction score from a survey scoped specifically to the used buying experience after delivery. | E38: Medallia CSAT average/top-box %, filtered to used post-purchase survey instance. | F38: Captures whether the product matched expectations set on the PDP, the buy-side counterpart to sell-flow CSAT. | G38: Impact | H38: Medallia | I38: Medallia Survey
A39: Used | B39: Increase Buy Used Reactivation | C39: Win-Back email open rate | D39: Share of sent win-back emails that were opened. | E39: Unique opens ÷ emails delivered. | F39: Same logic as trade-in reactivation, the entry checkpoint for the whole campaign. | G39: Adoption | H39: ESP
A40: Used | B40: Increase Buy Used Reactivation | C40: Win-back email CTR | D40: Share of sent win-back emails that resulted in a click. | E40: Unique clicks ÷ emails delivered (or ÷ opens for click-to-open). | F40: Tests whether the specific inventory/offer surfaced in the email is relevant enough to act on. | G40: Adoption | H40: ESP | I40: Email CTA
A41: Used | B41: Increase Buy Used Reactivation | C41: Browse to used PDP rate from email | D41: Of customers who clicked into the site from a win-back email, the share who viewed a used PDP during that session. | E41: Sessions with used PDP view ÷ sessions originating from win-back email click. | F41: Confirms the email is routing people to relevant used inventory, not just generic site traffic. | G41: Adoption | H41: GA4 + ESP | I41: Email CTA, Used PDP
...

Sheet GA4 (Don't Touch)
B2: Product_Type | C2: Element | D2: component type | E2: eventName | F2: component_GA4 | G2: label | H2: label_value | I2: site_type | J2: page_type | K2: Trigger & Other Parameters | L2: Flag
B3: N/A | D3: Page Load | E3: page_view | F3: — | G3: — | H3: — | I3: Desktop | J3: productList | K3: Initial render and every filter/sort/paging change (pushState)content_group: productList · site_langauge: E · bi: NoValue · pwa_source: NoValue · bh_user_id · category_page_id: 9811 | L3: observed
B4: N/A | D4: Page Load | E4: view_item_list | F4: — | G4: — | H4: — | I4: Desktop | J4: productList | K4: Results grid rendered — 28 items in one senditems[]: item_id, item_code, item_list_name, index, sales_comment · position_index: 1 | L4: observed
B5: N/A | D5: Page Load | E5: view_item_list | F5: — | G5: — | H5: — | I5: absent | J5: absent | K5: Google Ads remarketing duplicate — separate send, not the GA4 propertysend_to: google_ads · ecomm_pagetype: productList · ecomm_prodid[] · tag: AW-1056059933 | L5: by design
B6: N/A | D6: Page Load | E6: view_promotion | F6: — | G6: — | H6: — | I6: Desktop | J6: productList | K6: Hero banner impression — the Nikon trade-in unitcreative_name: IO Image Banner · creative_slot: HERO · promotion_name: 3385025 - BHUX 35089 Nikon Z6III Listing Page · promotion_url: /a/trade-in/64435 | L6: observed
B7: N/A | D7: Page Load | E7: view_promotion | F7: — | G7: — | H7: — | I7: Desktop | J7: productList | K7: Sponsored carousel — one event per slotcreative_name: spotfront list item · creative_slot: TOP · promotion_position: 1, 2, 3 · promotion_id (uuid) · promotion_url | L7: observed
B8: N/A | D8: Page Load | E8: view_promotion | F8: — | G8: — | H8: — | I8: Desktop | J8: productList | K8: Email slide-out and mega-menu banner impressionscreative_name: Email Slideout Signup / IO Banner · creative_slot: SLIDER / Top Nav · promotion_id: ESS | L8: observed
B9: New | C9: Homepage Banner | D9: Banner | E9: select_promotion
B10: New | C10: Top Nav | D10: Navigation | E10: mega_menu_clicks | F10: Top Nav | G10: Computers | H10: — | I10: Desktop | J10: category
B11: New | C11: New Mega Menu | D11: Navigation - Mega Menu | E11: mega_menu_clicks | F11: Pro Audio menu | G11: Live sound | H11: —
B12: New | C12: New Site Search Box | D12: Search | E12: header_clicks | F12: Search | G12: Enter Search | I12: Desktop | J12: home
B13: New | C13: New Site Search Type Ahead | D13: Search | E13: typeahead_suggestion_clicks | F13: Typeahead Suggestions | G13: — | H13: — | I13: — | J13: —
B14: New | C14: New Item Category Listing Page | D14: PLP | I14: Desktop | J14: productList
B15: New | C15: New Item Category Listing Page Product Card Used From CTA | D15: CTA | I15: Desktop | J15: productList
B16: N/A | C16: New Item Category Listing Page | D16: Refinements | E16: listing_page_clicks | F16: Filters | G16: — | H16: — | I16: Desktop | J16: productList | K16: Left-rail facet checkboxfilter_value: Full Frame (35mm) · filter_section: Sensor Size · filter_n_value: fct_sensor-size_3087 · from: left refinements | L16: observed
B17: N/A | C17: New Item Category Listing Page | D17: Refinements | E17: listing_page_clicks | F17: Filters | G17: — | H17: — | I17: Desktop | J17: productList | K17: Left-rail Categories link (Mirrorless Cameras)filter_value: "undefined" · filter_section: Category · filter_n_value: Mirrorless Cameras · from: "undefined" | L17: F1
B18: N/A | C18: New Item Category Listing Page | D18: Refinements | E18: listing_page_clicks | F18: Filter Labels | G18: Still Image Resolution | H18: — | I18: Desktop | J18: productList | K18: Facet accordion expand/collapse — label carries the section name | L18: observed
B19: N/A | C19: New Item Category Listing Page | D19: Refinements | E19: listing_page_clicks | F19: Listing See All Info | G19: left refinements | H19: — | I19: Desktop | J19: productList | K19: "See all + 10" opens the full-facet modal — label carries placement, not which facet | L19: F3
B20: N/A | C20: New Item Category Listing Page | D20: Refinements | E20: listing_page_clicks | F20: Listing See All Modal | G20: Clear All | H20: — | I20: Desktop | J20: productList | K20: Clear All inside the modal — the only modal control that emits anything | L20: F2
B21: N/A | C21: New Item Category Listing Page | D21: Listing Controls | E21: listing_page_clicks | F21: Sort By | G21: "" (empty) | H21: — | I21: Desktop | J21: productList | K21: Opening the sort dropdown — fires with an empty label before any choice is made | L21: F4
B22: N/A | C22: New Item Category Listing Page | D22: Listing Controls | E22: listing_page_clicks | F22: Sort By | G22: PRICE_LOW_TO_HIGH | H22: — | I22: Desktop | J22: productList | K22: Sort selected — label is the enum, not the visible "Price: Low to High" | L22: observed
B23: N/A | C23: New Item Category Listing Page | D23: Listing Controls | E23: listing_page_clicks | F23: View | G23: Grid View · List View | H23: — | I23: Desktop | J23: productList | K23: Grid/list density toggle | L23: observed
B24: N/A | C24: New Item Category Listing Page | D24: Listing Controls | E24: listing_page_clicks | F24: Paging | G24: page 2 | H24: — | I24: Desktop | J24: productList | K24: Pagination control — label is the literal "page " prefix plus the number | L24: observed
B25: New | D25: Product Title | E25: select_item | F25: Item List | G25: — | H25: — | I25: Desktop | J25: productList | K25: Product title click — GA4 ecommerce event, not a listing_page_clicksitems: [{ item_id }] · section_path: Category | L25: observed
B26: New | C26: New Item Category Listing Page Product Card | D26: Product Title | E26: listing_page_clicks | F26: Other Buying Options | G26: Used | H26: 1910936-REG | I26: Desktop | J26: productList | K26: "Used for $39.95" link on a tile — the only component on this page that populates label_valuesection_path: Category · label = buying-option type · label_value = SKU | L26: observed
B27: New | C27: New Item Category Listing Page Product Card | D27: Product Title | E27: listing_page_clicks | F27: Show More | G27: — | H27: — | I27: Desktop | J27: productList | K27: Expanding a tile's Key Featuressection_path: Category — no item_id, so it cannot be tied to a product | L27: F5
B28: New | C28: New Item Category Listing Page Product Card | D28: Product Title | E28: listing_page_clicks | F28: Add to Compare | G28: — | H28: — | I28: Desktop | J28: productList | K28: Compare checkbox on a tile — no label, no item identifier | L28: F5
B29: New | D29: Promo & Navigation | E29: select_promotion | F29: — | G29: — | H29: — | I29: Desktop | J29: productList | K29: Hero banner click — mirrors the view_promotion paramscreative_name: IO Image Banner · creative_slot: HERO · promotion_url: /a/trade-in/64435 | L29: observed
B30: New | D30: Promo & Navigation | E30: breadcrumbs | F30: Breadcrumb | G30: — | H30: — | I30: Desktop | J30: productList | K30: Breadcrumb link clickbreadcrumbs: Photography — destination in its own param rather than label | L30: observed
B31: New | C31: New Item Category Landing Page | D31: Navigation into the Catalog | E31: category_page_clicks | F31: Category Groups | G31: Cameras & Lenses | H31: Digital Cameras | I31: Desktop | J31: category | K31: Category tile — label is the section, label_value the destinationcategory_page_id: 989 | L31: model
B32: New | C32: New Item Category Landing Page | D32: Navigation into the Catalog | E32: category_page_clicks | F32: Category Groups | G32: Accessories | H32: Lens Accessories | I32: Desktop | J32: category | K32: Same component, second section — the convention holds across the page | L32: model
B33: New | C33: New Item Category Landing Page | D33: Navigation into the Catalog | E33: category_page_clicks | F33: Category Groups | G33: Applications | H33: Portrait Photography | I33: Desktop | J33: category | K33: The "What would you like to shoot?" rail — reports under its internal key, Applicationsthe only section whose label doesn't match its visible heading | L33: C3
B34: New | C34: New Item Category Landing Page | D34: Content & Banners | E34: category_page_clicks | F34: Explora banner | G34: Venus Optics Delivers Two New Ultra-Macro Laowa Lenses | H34: — | I34: Desktop | J34: category | K34: Editorial rail — label carries the full article title, so content performance is readable | L34: observed
B35: New | C35: New Item Category Landing Page | D35: Content & Banners | E35: category_page_clicks | F35: Category Banner | G35: — | H35: — | I35: Desktop | J35: category | K35: The Hasselblad "Learn More" unit — no label, so which brand banner was clicked is unknowable | L35: C2
B36: New | C36: New Item Category Landing Page | D36: Content & Banners | E36: category_page_clicks | F36: chatBanner | G36: — | H36: — | I36: Desktop | J36: category | K36: "Video Chat with a Photography Expert" strip — opens the chat widget, sends nothing about which expert path | L36: C2
B37: New | C37: New Item Category Landing Page | D37: Content & Banners | E37: category_page_clicks | F37: SEO Text | G37: Show More | H37: — | I37: Desktop | J37: category | K37: Expanding the bottom copy block — same component and label as on the listing page | L37: observed
B38: New | C38: New Item Category Landing Page | D38: Promo & Exits | E38: select_promotion | F38: — | G38: — | H38: — | I38: Desktop | J38: category | K38: Trade-in banner clicked — mirrors its impression event exactly, same promotion_idcreative_slot: TOP · promotion_url: /a/trade-in/64435 | L38: observed
B39: New | C39: New Item Category Landing Page | D39: Promo & Exits | E39: select_promotion | F39: — | G39: — | H39: — | I39: Desktop | J39: category | K39: Spotfront product rail item clicked — impression and click share promotion_id and promotion_position, so slot-level CTR is directly computable | L39: observed
B40: New | C40: New Item Category Landing Page | D40: Promo & Exits | E40: footer_clicks | F40: Trade in Your Gear | G40: — | H40: — | I40: Desktop | J40: category | K40: Footer trade-in link — a different event family from the banner above it, same destination | L40: C5
B41: N/A | C41: PDP | E41: view_item | F41: — | G41: — | H41: — | I41: Desktop | J41: productDetail | K41: Product rendered — the richest payload on the page, and still condition-blindcurrency: USD · value: 2136.95 · items: [{ item_id: 803528607-USE, item_code: 3528607, price: 2136.95, stock_status: IN_STOCK, shipping_message: FREE_ONE_DAY_DELIVERY, store_pickup_message: AVAILABLE_IN_PICKUP_TIME }] | L41: U1 U5
...

Sheet Roadmap 26-27 (Don't Touch)

Sheet Roadmap (Auto)
A1: 2026–2027 Product Roadmap — Swim Lanes by Theme
A2: Legend: | B2: Deliverables, themes and UX dates come from the Weekly tab · dev sprints from the Initiative Tracker | I2: U | J2: UX / design (Weekly) | O2: D | P2: Dev sprint (Tracker) | U2: B | V2: Both, same month | AA2: Amber column = current month
I3: 46023 | J3: 46054 | K3: 46082 | L3: 46113 | M3: 46143 | N3: 46174 | O3: 46204 | P3: 46235 | Q3: 46266 | R3: 46296 | S3: 46327 | T3: 46357 | U3: 46388 | V3: 46419 | W3: 46447 | X3: 46478 | Y3: 46508 | Z3: 46539 | AA3: 46569 | AB3: 46600 | AC3: 46631 | AD3: 46661 | AE3: 46692 | AF3: 46722
I4: 2026 | U4: 2027
I5: Q1 | L5: Q2 | O5: Q3 | R5: Q4 | U5: Q1 | X5: Q2 | AA5: Q3 | AD5: Q4
A6: Theme (swim lane) | B6: Deliverable | C6: Jira | D6: Status | E6: UX Start | F6: UX End | G6: Dev Start | H6: Dev End | I6: Jan | J6: Feb | K6: Mar | L6: Apr | M6: May | N6: Jun | O6: Jul | P6: Aug | Q6: Sep | R6: Oct | S6: Nov | T6: Dec | U6: Jan | V6: Feb | W6: Mar | X6: Apr | Y6: May | Z6: Jun | AA6: Jul | AB6: Aug | AC6: Sep | AD6: Oct | AE6: Nov | AF6: Dec | AG6: _theme | AH6: _row
A7: =IF($AH7="","",IF($AG7=$AG6,"",$AG7)) | B7: =IF($AH7="","",INDEX('Roadmap Calc (Don’t Touch)'!$B$2:$B$205,$AH7)) | C7: =IF($AH7="","",INDEX('Roadmap Calc (Don’t Touch)'!$E$2:$E$205,$AH7)) | D7: =IF($AH7="","",INDEX('Roadmap Calc (Don’t Touch)'!$F$2:$F$205,$AH7)) | E7: =IF($AH7="","",INDEX('Roadmap Calc (Don’t Touch)'!$G$2:$G$205,$AH7)) | F7: =IF($AH7="","",INDEX('Roadmap Calc (Don’t Touch)'!$H$2:$H$205,$AH7)) | G7: =IF($AH7="","",INDEX('Roadmap Calc (Don’t Touch)'!$I$2:$I$205,$AH7)) | H7: =IF($AH7="","",INDEX('Roadmap Calc (Don’t Touch)'!$J$2:$J$205,$AH7)) | I7: =IF($AH7="","",IF(AND($E7<>"",$E7<=EOMONTH(I$3,0),$F7>=I$3),IF(AND($G7<>"",$G7<=EOMONTH(I$3,0),$H7>=I$3),"B","U"),IF(AND($G7<>"",$G7<=EOMONTH(I$3,0),$H7>=I$3),"D",""))) | J7: =IF($AH7="","",IF(AND($E7<>"",$E7<=EOMONTH(J$3,0),$F7>=J$3),IF(AND($G7<>"",$G7<=EOMONTH(J$3,0),$H7>=J$3),"B","U"),IF(AND($G7<>"",$G7<=EOMONTH(J$3,0),$H7>=J$3),"D",""))) | K7: =IF($AH7="","",IF(AND($E7<>"",$E7<=EOMONTH(K$3,0),$F7>=K$3),IF(AND($G7<>"",$G7<=EOMONTH(K$3,0),$H7>=K$3),"B","U"),IF(AND($G7<>"",$G7<=EOMONTH(K$3,0),$H7>=K$3),"D",""))) | L7: =IF($AH7="","",IF(AND($E7<>"",$E7<=EOMONTH(L$3,0),$F7>=L$3),IF(AND($G7<>"",$G7<=EOMONTH(L$3,0),$H7>=L$3),"B","U"),IF(AND($G7<>"",$G7<=EOMONTH(L$3,0),$H7>=L$3),"D",""))) | M7: =IF($AH7="","",IF(AND($E7<>"",$E7<=EOMONTH(M$3,0),$F7>=M$3),IF(AND($G7<>"",$G7<=EOMONTH(M$3,0),$H7>=M$3),"B","U"),IF(AND($G7<>"",$G7<=EOMONTH(M$3,0),$H7>=M$3),"D",""))) | N7: =IF($AH7="","",IF(AND($E7<>"",$E7<=EOMONTH(N$3,0),$F7>=N$3),IF(AND($G7<>"",$G7<=EOMONTH(N$3,0),$H7>=N$3),"B","U"),IF(AND($G7<>"",$G7<=EOMONTH(N$3,0),$H7>=N$3),"D",""))) | O7: =IF($AH7="","",IF(AND($E7<>"",$E7<=EOMONTH(O$3,0),$F7>=O$3),IF(AND($G7<>"",$G7<=EOMONTH(O$3,0),$H7>=O$3),"B","U"),IF(AND($G7<>"",$G7<=EOMONTH(O$3,0),$H7>=O$3),"D",""))) | P7: =IF($AH7="","",IF(AND($E7<>"",$E7<=EOMONTH(P$3,0),$F7>=P$3),IF(AND($G7<>"",$G7<=EOMONTH(P$3,0),$H7>=P$3),"B","U"),IF(AND($G7<>"",$G7<=EOMONTH(P$3,0),$H7>=P$3),"D",""))) | ... AF7: =IF($AH7="","",IF(AND($E7<>"",$E7<=EOMONTH(AF$3,0),$F7>=AF$3),IF(AND($G7<>"",$G7<=EOMONTH(AF$3,0),$H7>=AF$3),"B","U"),IF(AND($G7<>"",$G7<=EOMONTH(AF$3,0),$H7>=AF$3),"D",""))) | AG7: =IF($AH7="","",INDEX('Roadmap Calc (Don’t Touch)'!$D$2:$D$205,$AH7)) | AH7: =IFERROR(MATCH(1,'Roadmap Calc (Don’t Touch)'!$O$2:$O$205,0),"")
A8: =IF($AH8="","",IF($AG8=$AG7,"",$AG8)) | B8: =IF($AH8="","",INDEX('Roadmap Calc (Don’t Touch)'!$B$2:$B$205,$AH8)) | C8: =IF($AH8="","",INDEX('Roadmap Calc (Don’t Touch)'!$E$2:$E$205,$AH8)) | D8: =IF($AH8="","",INDEX('Roadmap Calc (Don’t Touch)'!$F$2:$F$205,$AH8)) | E8: =IF($AH8="","",INDEX('Roadmap Calc (Don’t Touch)'!$G$2:$G$205,$AH8)) | F8: =IF($AH8="","",INDEX('Roadmap Calc (Don’t Touch)'!$H$2:$H$205,$AH8)) | G8: =IF($AH8="","",INDEX('Roadmap Calc (Don’t Touch)'!$I$2:$I$205,$AH8)) | H8: =IF($AH8="","",INDEX('Roadmap Calc (Don’t Touch)'!$J$2:$J$205,$AH8)) | I8: =IF($AH8="","",IF(AND($E8<>"",$E8<=EOMONTH(I$3,0),$F8>=I$3),IF(AND($G8<>"",$G8<=EOMONTH(I$3,0),$H8>=I$3),"B","U"),IF(AND($G8<>"",$G8<=EOMONTH(I$3,0),$H8>=I$3),"D",""))) | J8: =IF($AH8="","",IF(AND($E8<>"",$E8<=EOMONTH(J$3,0),$F8>=J$3),IF(AND($G8<>"",$G8<=EOMONTH(J$3,0),$H8>=J$3),"B","U"),IF(AND($G8<>"",$G8<=EOMONTH(J$3,0),$H8>=J$3),"D",""))) | K8: =IF($AH8="","",IF(AND($E8<>"",$E8<=EOMONTH(K$3,0),$F8>=K$3),IF(AND($G8<>"",$G8<=EOMONTH(K$3,0),$H8>=K$3),"B","U"),IF(AND($G8<>"",$G8<=EOMONTH(K$3,0),$H8>=K$3),"D",""))) | L8: =IF($AH8="","",IF(AND($E8<>"",$E8<=EOMONTH(L$3,0),$F8>=L$3),IF(AND($G8<>"",$G8<=EOMONTH(L$3,0),$H8>=L$3),"B","U"),IF(AND($G8<>"",$G8<=EOMONTH(L$3,0),$H8>=L$3),"D",""))) | M8: =IF($AH8="","",IF(AND($E8<>"",$E8<=EOMONTH(M$3,0),$F8>=M$3),IF(AND($G8<>"",$G8<=EOMONTH(M$3,0),$H8>=M$3),"B","U"),IF(AND($G8<>"",$G8<=EOMONTH(M$3,0),$H8>=M$3),"D",""))) | N8: =IF($AH8="","",IF(AND($E8<>"",$E8<=EOMONTH(N$3,0),$F8>=N$3),IF(AND($G8<>"",$G8<=EOMONTH(N$3,0),$H8>=N$3),"B","U"),IF(AND($G8<>"",$G8<=EOMONTH(N$3,0),$H8>=N$3),"D",""))) | O8: =IF($AH8="","",IF(AND($E8<>"",$E8<=EOMONTH(O$3,0),$F8>=O$3),IF(AND($G8<>"",$G8<=EOMONTH(O$3,0),$H8>=O$3),"B","U"),IF(AND($G8<>"",$G8<=EOMONTH(O$3,0),$H8>=O$3),"D",""))) | P8: =IF($AH8="","",IF(AND($E8<>"",$E8<=EOMONTH(P$3,0),$F8>=P$3),IF(AND($G8<>"",$G8<=EOMONTH(P$3,0),$H8>=P$3),"B","U"),IF(AND($G8<>"",$G8<=EOMONTH(P$3,0),$H8>=P$3),"D",""))) | ... AF8: =IF($AH8="","",IF(AND($E8<>"",$E8<=EOMONTH(AF$3,0),$F8>=AF$3),IF(AND($G8<>"",$G8<=EOMONTH(AF$3,0),$H8>=AF$3),"B","U"),IF(AND($G8<>"",$G8<=EOMONTH(AF$3,0),$H8>=AF$3),"D",""))) | AG8: =IF($AH8="","",INDEX('Roadmap Calc (Don’t Touch)'!$D$2:$D$205,$AH8)) | AH8: =IFERROR(MATCH(2,'Roadmap Calc (Don’t Touch)'!$O$2:$O$205,0),"")
A9: =IF($AH9="","",IF($AG9=$AG8,"",$AG9)) | B9: =IF($AH9="","",INDEX('Roadmap Calc (Don’t Touch)'!$B$2:$B$205,$AH9)) | C9: =IF($AH9="","",INDEX('Roadmap Calc (Don’t Touch)'!$E$2:$E$205,$AH9)) | D9: =IF($AH9="","",INDEX('Roadmap Calc (Don’t Touch)'!$F$2:$F$205,$AH9)) | E9: =IF($AH9="","",INDEX('Roadmap Calc (Don’t Touch)'!$G$2:$G$205,$AH9)) | F9: =IF($AH9="","",INDEX('Roadmap Calc (Don’t Touch)'!$H$2:$H$205,$AH9)) | G9: =IF($AH9="","",INDEX('Roadmap Calc (Don’t Touch)'!$I$2:$I$205,$AH9)) | H9: =IF($AH9="","",INDEX('Roadmap Calc (Don’t Touch)'!$J$2:$J$205,$AH9)) | I9: =IF($AH9="","",IF(AND($E9<>"",$E9<=EOMONTH(I$3,0),$F9>=I$3),IF(AND($G9<>"",$G9<=EOMONTH(I$3,0),$H9>=I$3),"B","U"),IF(AND($G9<>"",$G9<=EOMONTH(I$3,0),$H9>=I$3),"D",""))) | J9: =IF($AH9="","",IF(AND($E9<>"",$E9<=EOMONTH(J$3,0),$F9>=J$3),IF(AND($G9<>"",$G9<=EOMONTH(J$3,0),$H9>=J$3),"B","U"),IF(AND($G9<>"",$G9<=EOMONTH(J$3,0),$H9>=J$3),"D",""))) | K9: =IF($AH9="","",IF(AND($E9<>"",$E9<=EOMONTH(K$3,0),$F9>=K$3),IF(AND($G9<>"",$G9<=EOMONTH(K$3,0),$H9>=K$3),"B","U"),IF(AND($G9<>"",$G9<=EOMONTH(K$3,0),$H9>=K$3),"D",""))) | L9: =IF($AH9="","",IF(AND($E9<>"",$E9<=EOMONTH(L$3,0),$F9>=L$3),IF(AND($G9<>"",$G9<=EOMONTH(L$3,0),$H9>=L$3),"B","U"),IF(AND($G9<>"",$G9<=EOMONTH(L$3,0),$H9>=L$3),"D",""))) | M9: =IF($AH9="","",IF(AND($E9<>"",$E9<=EOMONTH(M$3,0),$F9>=M$3),IF(AND($G9<>"",$G9<=EOMONTH(M$3,0),$H9>=M$3),"B","U"),IF(AND($G9<>"",$G9<=EOMONTH(M$3,0),$H9>=M$3),"D",""))) | N9: =IF($AH9="","",IF(AND($E9<>"",$E9<=EOMONTH(N$3,0),$F9>=N$3),IF(AND($G9<>"",$G9<=EOMONTH(N$3,0),$H9>=N$3),"B","U"),IF(AND($G9<>"",$G9<=EOMONTH(N$3,0),$H9>=N$3),"D",""))) | O9: =IF($AH9="","",IF(AND($E9<>"",$E9<=EOMONTH(O$3,0),$F9>=O$3),IF(AND($G9<>"",$G9<=EOMONTH(O$3,0),$H9>=O$3),"B","U"),IF(AND($G9<>"",$G9<=EOMONTH(O$3,0),$H9>=O$3),"D",""))) | P9: =IF($AH9="","",IF(AND($E9<>"",$E9<=EOMONTH(P$3,0),$F9>=P$3),IF(AND($G9<>"",$G9<=EOMONTH(P$3,0),$H9>=P$3),"B","U"),IF(AND($G9<>"",$G9<=EOMONTH(P$3,0),$H9>=P$3),"D",""))) | ... AF9: =IF($AH9="","",IF(AND($E9<>"",$E9<=EOMONTH(AF$3,0),$F9>=AF$3),IF(AND($G9<>"",$G9<=EOMONTH(AF$3,0),$H9>=AF$3),"B","U"),IF(AND($G9<>"",$G9<=EOMONTH(AF$3,0),$H9>=AF$3),"D",""))) | AG9: =IF($AH9="","",INDEX('Roadmap Calc (Don’t Touch)'!$D$2:$D$205,$AH9)) | AH9: =IFERROR(MATCH(3,'Roadmap Calc (Don’t Touch)'!$O$2:$O$205,0),"")
