Workbook

Sheet Roadmap (Auto)
A1: Product Roadmap - 2026-2027 | D1: ="Showing "&COUNTIF('Roadmap Calc (Don’t Touch)'!$V$2:$V$151,1)&" of "&COUNTIF('Roadmap Calc (Don’t Touch)'!$V$2:$V$151,">=0")&" rows" -> Showing 25 of 47 rows | AJ1: (All) | AK1: (All) | AL1: (All) | AM1: Theme, then Status
A2: Select Portfolio | B2: Select Theme | C2: Select Status | D2: Sort by
A3: Used | B3: (All) | C3: (All)
AJ4: =IF(COUNTA(Control!A4)=0,"",Control!A4) -> B2B | AK4: =IF(COUNTA(Control!E4)=0,"",Control!E4) -> Improve Discovery | AL4: =IF(COUNTA(Control!B4)=0,"",Control!B4) -> 00. Parking Lot | AM4: Status, then Theme
AJ5: =IF(COUNTA(Control!A5)=0,"",Control!A5) -> Used | AK5: =IF(COUNTA(Control!E5)=0,"",Control!E5) -> Increase Trade In Awareness | AL5: =IF(COUNTA(Control!B5)=0,"",Control!B5) -> 01A. Research - Foundational | AM5: Dev start (earliest)
K6: PD | L6: Prod Disc | N6: UX | O6: UX work | Q6: DEV | R6: Dev sprint | T6: PD+UX | U6: Disc+UX | W6: PD+DEV | X6: Disc+Dev | Z6: UX+DEV | AA6: UX+Dev | AC6: ALL | AD6: All three
A7: Description | B7: =IF(OR($B$3="",$B$3="(All)"),"Hint: Pick a theme in Show theme above to see its description and measures.",IF('Roadmap Calc (Don’t Touch)'!$BA$5="","— no description defined on the Control tab —",'Roadmap Calc (Don’t Touch)'!$BA$5)) -> Hint: Pick a theme in Show theme above to see its description and measures. | AJ7: =IF(COUNTA(Control!A6)=0,"",Control!A6) -> Find | AK7: =IF(COUNTA(Control!E6)=0,"",Control!E6) -> Improve Trade In User Flow | AL7: =IF(COUNTA(Control!B6)=0,"",Control!B6) -> 01. Prod Discovery | AM7: UX start (earliest)
A8: Measure adoption | B8: =IF(OR($B$3="",$B$3="(All)"),"",IF('Roadmap Calc (Don’t Touch)'!$BA$6="","— no adoption measures defined on the Control tab —",'Roadmap Calc (Don’t Touch)'!$BA$6)) | AJ8: =IF(COUNTA(Control!A7)=0,"",Control!A7) | AK8: =IF(COUNTA(Control!E7)=0,"",Control!E7) -> Increase Trade In Reactivation | AL8: =IF(COUNTA(Control!B7)=0,"",Control!B7) -> 02. UX Req | AM8: Deliverable A-Z
A9: Measure impact | B9: =IF(OR($B$3="",$B$3="(All)"),"",IF('Roadmap Calc (Don’t Touch)'!$BA$7="","— no impact measures defined on the Control tab —",'Roadmap Calc (Don’t Touch)'!$BA$7)) | AJ9: =IF(COUNTA(Control!A8)=0,"",Control!A8) | AK9: =IF(COUNTA(Control!E8)=0,"",Control!E8) -> Increase Buy Used Awareness | AL9: =IF(COUNTA(Control!B8)=0,"",Control!B8) -> 03. UX Discovery
AJ11: =IF(COUNTA(Control!A9)=0,"",Control!A9) | AK11: =IF(COUNTA(Control!E9)=0,"",Control!E9) -> Improve Buy Used Customer Experience | AL11: =IF(COUNTA(Control!B9)=0,"",Control!B9) -> 04. UX Design
J12: 46023 | K12: 46054 | L12: 46082 | M12: 46113 | N12: 46143 | O12: 46174 | P12: 46204 | Q12: 46235 | R12: 46266 | S12: 46296 | T12: 46327 | U12: 46357 | V12: 46388 | W12: 46419 | X12: 46447 | Y12: 46478 | Z12: 46508 | AA12: 46539 | AB12: 46569 | AC12: 46600 | AD12: 46631 | AE12: 46661 | AF12: 46692 | AG12: 46722 | AK12: =IF(COUNTA(Control!E10)=0,"",Control!E10) -> Increase Buy Used Reactivation | AL12: =IF(COUNTA(Control!B10)=0,"",Control!B10) -> 04A. Research - Design Validation
A13: Product Goal: Grow B2B Platforms, Used and Trade-In verticals while elevating content quality across the site. | J13: 2026 | V13: 2027 | AK13: =IF(COUNTA(Control!E11)=0,"",Control!E11) -> Increase B2B Acquisition | AL13: =IF(COUNTA(Control!B11)=0,"",Control!B11) -> 05. Business Review
J14: Q1 | M14: Q2 | P14: Q3 | S14: Q4 | V14: Q1 | Y14: Q2 | AB14: Q3 | AE14: Q4 | AK14: =IF(COUNTA(Control!E12)=0,"",Control!E12) -> Increase The Studio B&H Awareness | AL14: =IF(COUNTA(Control!B12)=0,"",Control!B12) -> 06. Architecture
A15: Theme (swim lane) | B15: Deliverable (BHP Link) | C15: Jira | D15: Status | E15: UX From | F15: UX To | G15: UX Wks | H15: Dev From | I15: Dev To | J15: Jan | K15: Feb | L15: Mar | M15: Apr | N15: May | O15: Jun | P15: Jul | Q15: Aug | R15: Sep | S15: Oct | T15: Nov | U15: Dec | V15: Jan | W15: Feb | X15: Mar | Y15: Apr | Z15: May | AA15: Jun | AB15: Jul | AC15: Aug | AD15: Sep | AE15: Oct | AF15: Nov | AG15: Dec | AH15: _theme | AI15: _row | AK15: =IF(COUNTA(Control!E13)=0,"",Control!E13) -> Improve The Studio B&H Customer Experience | AL15: =IF(COUNTA(Control!B13)=0,"",Control!B13) -> 07. Grooming
A16: =IF($AI16="","",IF($AH16=$AH15,"",IF(INDEX('Roadmap Calc (Don’t Touch)'!$U$2:$U$151,$AI16)=0,$AH16,HYPERLINK("#'Control (Don’t Touch)'!E"&INDEX('Roadmap Calc (Don’t Touch)'!$U$2:$U$151,$AI16),$AH16)))) -> Increase Trade In Awareness | B16: =IF($AI16="","",IF(INDEX('Roadmap Calc (Don’t Touch)'!$K$2:$K$151,$AI16)="",INDEX('Roadmap Calc (Don’t Touch)'!$B$2:$B$151,$AI16),HYPERLINK("https://jira.bnh.com/browse/"&INDEX('Roadmap Calc (Don’t Touch)'!$K$2:$K$151,$AI16),INDEX('Roadmap Calc (Don’t Touch)'!$B$2:$B$151,$AI16)))) -> Decouple Sell Used from Used Hub | C16: =IF($AI16="","",IF(INDEX('Roadmap Calc (Don’t Touch)'!$E$2:$E$151,$AI16)="","",HYPERLINK("https://jira.bnh.com/browse/"&INDEX('Roadmap Calc (Don’t Touch)'!$E$2:$E$151,$AI16),INDEX('Roadmap Calc (Don’t Touch)'!$E$2:$E$151,$AI16)))) -> BHP-7431 | D16: =IF($AI16="","",INDEX('Roadmap Calc (Don’t Touch)'!$F$2:$F$151,$AI16)) -> 01. Prod Discovery | E16: =IF($AI16="","",IF(ISNUMBER(INDEX('Roadmap Calc (Don’t Touch)'!$G$2:$G$151,$AI16)),INDEX('Roadmap Calc (Don’t Touch)'!$G$2:$G$151,$AI16),"")) | F16: =IF($AI16="","",IF(ISNUMBER(INDEX('Roadmap Calc (Don’t Touch)'!$H$2:$H$151,$AI16)),INDEX('Roadmap Calc (Don’t Touch)'!$H$2:$H$151,$AI16),"")) | G16: =IF($AI16="","",INDEX('Roadmap Calc (Don’t Touch)'!$T$2:$T$151,$AI16)) -> 0 | H16: =IF($AI16="","",IF(ISNUMBER(INDEX('Roadmap Calc (Don’t Touch)'!$I$2:$I$151,$AI16)),INDEX('Roadmap Calc (Don’t Touch)'!$I$2:$I$151,$AI16),"")) -> 46419 | I16: =IF($AI16="","",IF(ISNUMBER(INDEX('Roadmap Calc (Don’t Touch)'!$J$2:$J$151,$AI16)),INDEX('Roadmap Calc (Don’t Touch)'!$J$2:$J$151,$AI16),"")) -> 46446 | J16: =IF($AI16="","",IF(AND($AN16<>"",$AN16<=EOMONTH(J$12,0),$AO16>=J$12),IF(AND(INDEX('Roadmap Calc (Don’t Touch)'!$AA$2:$AX$151,$AI16,COLUMN()-COLUMN($J$16)+1)>0,OR($D16="03. UX Discovery",$D16="04. UX Design")),IF(AND($H16<>"",$H16<=EOMONTH(J$12,0),$I16>=J$12),"ALL","PD+UX"),IF(AND($H16<>"",$H16<=EOMONTH(J$12,0),$I16>=J$12),"PD+DEV","PD")),IF(AND(INDEX('Roadmap Calc (Don’t Touch)'!$AA$2:$AX$151,$AI16,COLUMN()-COLUMN($J$16)+1)>0,OR($D16="03. UX Discovery",$D16="04. UX Design")),IF(AND($H16<>"",$H16<=EOMONTH(J$12,0),$I16>=J$12),"UX+DEV","UX"),IF(AND($H16<>"",$H16<=EOMONTH(J$12,0),$I16>=J$12),"DEV","")))) | K16: =IF($AI16="","",IF(AND($AN16<>"",$AN16<=EOMONTH(K$12,0),$AO16>=K$12),IF(AND(INDEX('Roadmap Calc (Don’t Touch)'!$AA$2:$AX$151,$AI16,COLUMN()-COLUMN($J$16)+1)>0,OR($D16="03. UX Discovery",$D16="04. UX Design")),IF(AND($H16<>"",$H16<=EOMONTH(K$12,0),$I16>=K$12),"ALL","PD+UX"),IF(AND($H16<>"",$H16<=EOMONTH(K$12,0),$I16>=K$12),"PD+DEV","PD")),IF(AND(INDEX('Roadmap Calc (Don’t Touch)'!$AA$2:$AX$151,$AI16,COLUMN()-COLUMN($J$16)+1)>0,OR($D16="03. UX Discovery",$D16="04. UX Design")),IF(AND($H16<>"",$H16<=EOMONTH(K$12,0),$I16>=K$12),"UX+DEV","UX"),IF(AND($H16<>"",$H16<=EOMONTH(K$12,0),$I16>=K$12),"DEV","")))) | L16: =IF($AI16="","",IF(AND($AN16<>"",$AN16<=EOMONTH(L$12,0),$AO16>=L$12),IF(AND(INDEX('Roadmap Calc (Don’t Touch)'!$AA$2:$AX$151,$AI16,COLUMN()-COLUMN($J$16)+1)>0,OR($D16="03. UX Discovery",$D16="04. UX Design")),IF(AND($H16<>"",$H16<=EOMONTH(L$12,0),$I16>=L$12),"ALL","PD+UX"),IF(AND($H16<>"",$H16<=EOMONTH(L$12,0),$I16>=L$12),"PD+DEV","PD")),IF(AND(INDEX('Roadmap Calc (Don’t Touch)'!$AA$2:$AX$151,$AI16,COLUMN()-COLUMN($J$16)+1)>0,OR($D16="03. UX Discovery",$D16="04. UX Design")),IF(AND($H16<>"",$H16<=EOMONTH(L$12,0),$I16>=L$12),"UX+DEV","UX"),IF(AND($H16<>"",$H16<=EOMONTH(L$12,0),$I16>=L$12),"DEV","")))) | M16: =IF($AI16="","",IF(AND($AN16<>"",$AN16<=EOMONTH(M$12,0),$AO16>=M$12),IF(AND(INDEX('Roadmap Calc (Don’t Touch)'!$AA$2:$AX$151,$AI16,COLUMN()-COLUMN($J$16)+1)>0,OR($D16="03. UX Discovery",$D16="04. UX Design")),IF(AND($H16<>"",$H16<=EOMONTH(M$12,0),$I16>=M$12),"ALL","PD+UX"),IF(AND($H16<>"",$H16<=EOMONTH(M$12,0),$I16>=M$12),"PD+DEV","PD")),IF(AND(INDEX('Roadmap Calc (Don’t Touch)'!$AA$2:$AX$151,$AI16,COLUMN()-COLUMN($J$16)+1)>0,OR($D16="03. UX Discovery",$D16="04. UX Design")),IF(AND($H16<>"",$H16<=EOMONTH(M$12,0),$I16>=M$12),"UX+DEV","UX"),IF(AND($H16<>"",$H16<=EOMONTH(M$12,0),$I16>=M$12),"DEV","")))) | N16: =IF($AI16="","",IF(AND($AN16<>"",$AN16<=EOMONTH(N$12,0),$AO16>=N$12),IF(AND(INDEX('Roadmap Calc (Don’t Touch)'!$AA$2:$AX$151,$AI16,COLUMN()-COLUMN($J$16)+1)>0,OR($D16="03. UX Discovery",$D16="04. UX Design")),IF(AND($H16<>"",$H16<=EOMONTH(N$12,0),$I16>=N$12),"ALL","PD+UX"),IF(AND($H16<>"",$H16<=EOMONTH(N$12,0),$I16>=N$12),"PD+DEV","PD")),IF(AND(INDEX('Roadmap Calc (Don’t Touch)'!$AA$2:$AX$151,$AI16,COLUMN()-COLUMN($J$16)+1)>0,OR($D16="03. UX Discovery",$D16="04. UX Design")),IF(AND($H16<>"",$H16<=EOMONTH(N$12,0),$I16>=N$12),"UX+DEV","UX"),IF(AND($H16<>"",$H16<=EOMONTH(N$12,0),$I16>=N$12),"DEV","")))) | O16: =IF($AI16="","",IF(AND($AN16<>"",$AN16<=EOMONTH(O$12,0),$AO16>=O$12),IF(AND(INDEX('Roadmap Calc (Don’t Touch)'!$AA$2:$AX$151,$AI16,COLUMN()-COLUMN($J$16)+1)>0,OR($D16="03. UX Discovery",$D16="04. UX Design")),IF(AND($H16<>"",$H16<=EOMONTH(O$12,0),$I16>=O$12),"ALL","PD+UX"),IF(AND($H16<>"",$H16<=EOMONTH(O$12,0),$I16>=O$12),"PD+DEV","PD")),IF(AND(INDEX('Roadmap Calc (Don’t Touch)'!$AA$2:$AX$151,$AI16,COLUMN()-COLUMN($J$16)+1)>0,OR($D16="03. UX Discovery",$D16="04. UX Design")),IF(AND($H16<>"",$H16<=EOMONTH(O$12,0),$I16>=O$12),"UX+DEV","UX"),IF(AND($H16<>"",$H16<=EOMONTH(O$12,0),$I16>=O$12),"DEV","")))) | P16: =IF($AI16="","",IF(AND($AN16<>"",$AN16<=EOMONTH(P$12,0),$AO16>=P$12),IF(AND(INDEX('Roadmap Calc (Don’t Touch)'!$AA$2:$AX$151,$AI16,COLUMN()-COLUMN($J$16)+1)>0,OR($D16="03. UX Discovery",$D16="04. UX Design")),IF(AND($H16<>"",$H16<=EOMONTH(P$12,0),$I16>=P$12),"ALL","PD+UX"),IF(AND($H16<>"",$H16<=EOMONTH(P$12,0),$I16>=P$12),"PD+DEV","PD")),IF(AND(INDEX('Roadmap Calc (Don’t Touch)'!$AA$2:$AX$151,$AI16,COLUMN()-COLUMN($J$16)+1)>0,OR($D16="03. UX Discovery",$D16="04. UX Design")),IF(AND($H16<>"",$H16<=EOMONTH(P$12,0),$I16>=P$12),"UX+DEV","UX"),IF(AND($H16<>"",$H16<=EOMONTH(P$12,0),$I16>=P$12),"DEV","")))) | Q16: =IF($AI16="","",IF(AND($AN16<>"",$AN16<=EOMONTH(Q$12,0),$AO16>=Q$12),IF(AND(INDEX('Roadmap Calc (Don’t Touch)'!$AA$2:$AX$151,$AI16,COLUMN()-COLUMN($J$16)+1)>0,OR($D16="03. UX Discovery",$D16="04. UX Design")),IF(AND($H16<>"",$H16<=EOMONTH(Q$12,0),$I16>=Q$12),"ALL","PD+UX"),IF(AND($H16<>"",$H16<=EOMONTH(Q$12,0),$I16>=Q$12),"PD+DEV","PD")),IF(AND(INDEX('Roadmap Calc (Don’t Touch)'!$AA$2:$AX$151,$AI16,COLUMN()-COLUMN($J$16)+1)>0,OR($D16="03. UX Discovery",$D16="04. UX Design")),IF(AND($H16<>"",$H16<=EOMONTH(Q$12,0),$I16>=Q$12),"UX+DEV","UX"),IF(AND($H16<>"",$H16<=EOMONTH(Q$12,0),$I16>=Q$12),"DEV","")))) | ... AG16: =IF($AI16="","",IF(AND($AN16<>"",$AN16<=EOMONTH(AG$12,0),$AO16>=AG$12),IF(AND(INDEX('Roadmap Calc (Don’t Touch)'!$AA$2:$AX$151,$AI16,COLUMN()-COLUMN($J$16)+1)>0,OR($D16="03. UX Discovery",$D16="04. UX Design")),IF(AND($H16<>"",$H16<=EOMONTH(AG$12,0),$I16>=AG$12),"ALL","PD+UX"),IF(AND($H16<>"",$H16<=EOMONTH(AG$12,0),$I16>=AG$12),"PD+DEV","PD")),IF(AND(INDEX('Roadmap Calc (Don’t Touch)'!$AA$2:$AX$151,$AI16,COLUMN()-COLUMN($J$16)+1)>0,OR($D16="03. UX Discovery",$D16="04. UX Design")),IF(AND($H16<>"",$H16<=EOMONTH(AG$12,0),$I16>=AG$12),"UX+DEV","UX"),IF(AND($H16<>"",$H16<=EOMONTH(AG$12,0),$I16>=AG$12),"DEV","")))) | AH16: =IF($AI16="","",INDEX('Roadmap Calc (Don’t Touch)'!$D$2:$D$151,$AI16)) -> Increase Trade In Awareness | AI16: =IFERROR(MATCH(1,'Roadmap Calc (Don’t Touch)'!$O$2:$O$151,0),"") -> 7 | AK16: =IF(COUNTA(Control!E14)=0,"",Control!E14) -> Increase Trust & Condition Transparency | AL16: =IF(COUNTA(Control!B14)=0,"",Control!B14) -> 08. Ready for Dev | AN16: =IF($AI16="","",IF(ISNUMBER(INDEX('Roadmap Calc (Don’t Touch)'!$BB$2:$BB$151,$AI16)),INDEX('Roadmap Calc (Don’t Touch)'!$BB$2:$BB$151,$AI16),"")) | AO16: =IF($AI16="","",IF(ISNUMBER(INDEX('Roadmap Calc (Don’t Touch)'!$BC$2:$BC$151,$AI16)),INDEX('Roadmap Calc (Don’t Touch)'!$BC$2:$BC$151,$AI16),""))
A17: =IF($AI17="","",IF($AH17=$AH16,"",IF(INDEX('Roadmap Calc (Don’t Touch)'!$U$2:$U$151,$AI17)=0,$AH17,HYPERLINK("#'Control (Don’t Touch)'!E"&INDEX('Roadmap Calc (Don’t Touch)'!$U$2:$U$151,$AI17),$AH17)))) | B17: =IF($AI17="","",IF(INDEX('Roadmap Calc (Don’t Touch)'!$K$2:$K$151,$AI17)="",INDEX('Roadmap Calc (Don’t Touch)'!$B$2:$B$151,$AI17),HYPERLINK("https://jira.bnh.com/browse/"&INDEX('Roadmap Calc (Don’t Touch)'!$K$2:$K$151,$AI17),INDEX('Roadmap Calc (Don’t Touch)'!$B$2:$B$151,$AI17)))) -> Sell Used Mega Menu | C17: =IF($AI17="","",IF(INDEX('Roadmap Calc (Don’t Touch)'!$E$2:$E$151,$AI17)="","",HYPERLINK("https://jira.bnh.com/browse/"&INDEX('Roadmap Calc (Don’t Touch)'!$E$2:$E$151,$AI17),INDEX('Roadmap Calc (Don’t Touch)'!$E$2:$E$151,$AI17)))) -> BHP-7430 | D17: =IF($AI17="","",INDEX('Roadmap Calc (Don’t Touch)'!$F$2:$F$151,$AI17)) -> 01. Prod Discovery | E17: =IF($AI17="","",IF(ISNUMBER(INDEX('Roadmap Calc (Don’t Touch)'!$G$2:$G$151,$AI17)),INDEX('Roadmap Calc (Don’t Touch)'!$G$2:$G$151,$AI17),"")) -> 46286 | F17: =IF($AI17="","",IF(ISNUMBER(INDEX('Roadmap Calc (Don’t Touch)'!$H$2:$H$151,$AI17)),INDEX('Roadmap Calc (Don’t Touch)'!$H$2:$H$151,$AI17),"")) -> 46293 | G17: =IF($AI17="","",INDEX('Roadmap Calc (Don’t Touch)'!$T$2:$T$151,$AI17)) -> 2 | H17: =IF($AI17="","",IF(ISNUMBER(INDEX('Roadmap Calc (Don’t Touch)'!$I$2:$I$151,$AI17)),INDEX('Roadmap Calc (Don’t Touch)'!$I$2:$I$151,$AI17),"")) | I17: =IF($AI17="","",IF(ISNUMBER(INDEX('Roadmap Calc (Don’t Touch)'!$J$2:$J$151,$AI17)),INDEX('Roadmap Calc (Don’t Touch)'!$J$2:$J$151,$AI17),"")) | J17: =IF($AI17="","",IF(AND($AN17<>"",$AN17<=EOMONTH(J$12,0),$AO17>=J$12),IF(AND(INDEX('Roadmap Calc (Don’t Touch)'!$AA$2:$AX$151,$AI17,COLUMN()-COLUMN($J$16)+1)>0,OR($D17="03. UX Discovery",$D17="04. UX Design")),IF(AND($H17<>"",$H17<=EOMONTH(J$12,0),$I17>=J$12),"ALL","PD+UX"),IF(AND($H17<>"",$H17<=EOMONTH(J$12,0),$I17>=J$12),"PD+DEV","PD")),IF(AND(INDEX('Roadmap Calc (Don’t Touch)'!$AA$2:$AX$151,$AI17,COLUMN()-COLUMN($J$16)+1)>0,OR($D17="03. UX Discovery",$D17="04. UX Design")),IF(AND($H17<>"",$H17<=EOMONTH(J$12,0),$I17>=J$12),"UX+DEV","UX"),IF(AND($H17<>"",$H17<=EOMONTH(J$12,0),$I17>=J$12),"DEV","")))) | K17: =IF($AI17="","",IF(AND($AN17<>"",$AN17<=EOMONTH(K$12,0),$AO17>=K$12),IF(AND(INDEX('Roadmap Calc (Don’t Touch)'!$AA$2:$AX$151,$AI17,COLUMN()-COLUMN($J$16)+1)>0,OR($D17="03. UX Discovery",$D17="04. UX Design")),IF(AND($H17<>"",$H17<=EOMONTH(K$12,0),$I17>=K$12),"ALL","PD+UX"),IF(AND($H17<>"",$H17<=EOMONTH(K$12,0),$I17>=K$12),"PD+DEV","PD")),IF(AND(INDEX('Roadmap Calc (Don’t Touch)'!$AA$2:$AX$151,$AI17,COLUMN()-COLUMN($J$16)+1)>0,OR($D17="03. UX Discovery",$D17="04. UX Design")),IF(AND($H17<>"",$H17<=EOMONTH(K$12,0),$I17>=K$12),"UX+DEV","UX"),IF(AND($H17<>"",$H17<=EOMONTH(K$12,0),$I17>=K$12),"DEV","")))) | L17: =IF($AI17="","",IF(AND($AN17<>"",$AN17<=EOMONTH(L$12,0),$AO17>=L$12),IF(AND(INDEX('Roadmap Calc (Don’t Touch)'!$AA$2:$AX$151,$AI17,COLUMN()-COLUMN($J$16)+1)>0,OR($D17="03. UX Discovery",$D17="04. UX Design")),IF(AND($H17<>"",$H17<=EOMONTH(L$12,0),$I17>=L$12),"ALL","PD+UX"),IF(AND($H17<>"",$H17<=EOMONTH(L$12,0),$I17>=L$12),"PD+DEV","PD")),IF(AND(INDEX('Roadmap Calc (Don’t Touch)'!$AA$2:$AX$151,$AI17,COLUMN()-COLUMN($J$16)+1)>0,OR($D17="03. UX Discovery",$D17="04. UX Design")),IF(AND($H17<>"",$H17<=EOMONTH(L$12,0),$I17>=L$12),"UX+DEV","UX"),IF(AND($H17<>"",$H17<=EOMONTH(L$12,0),$I17>=L$12),"DEV","")))) | M17: =IF($AI17="","",IF(AND($AN17<>"",$AN17<=EOMONTH(M$12,0),$AO17>=M$12),IF(AND(INDEX('Roadmap Calc (Don’t Touch)'!$AA$2:$AX$151,$AI17,COLUMN()-COLUMN($J$16)+1)>0,OR($D17="03. UX Discovery",$D17="04. UX Design")),IF(AND($H17<>"",$H17<=EOMONTH(M$12,0),$I17>=M$12),"ALL","PD+UX"),IF(AND($H17<>"",$H17<=EOMONTH(M$12,0),$I17>=M$12),"PD+DEV","PD")),IF(AND(INDEX('Roadmap Calc (Don’t Touch)'!$AA$2:$AX$151,$AI17,COLUMN()-COLUMN($J$16)+1)>0,OR($D17="03. UX Discovery",$D17="04. UX Design")),IF(AND($H17<>"",$H17<=EOMONTH(M$12,0),$I17>=M$12),"UX+DEV","UX"),IF(AND($H17<>"",$H17<=EOMONTH(M$12,0),$I17>=M$12),"DEV","")))) | N17: =IF($AI17="","",IF(AND($AN17<>"",$AN17<=EOMONTH(N$12,0),$AO17>=N$12),IF(AND(INDEX('Roadmap Calc (Don’t Touch)'!$AA$2:$AX$151,$AI17,COLUMN()-COLUMN($J$16)+1)>0,OR($D17="03. UX Discovery",$D17="04. UX Design")),IF(AND($H17<>"",$H17<=EOMONTH(N$12,0),$I17>=N$12),"ALL","PD+UX"),IF(AND($H17<>"",$H17<=EOMONTH(N$12,0),$I17>=N$12),"PD+DEV","PD")),IF(AND(INDEX('Roadmap Calc (Don’t Touch)'!$AA$2:$AX$151,$AI17,COLUMN()-COLUMN($J$16)+1)>0,OR($D17="03. UX Discovery",$D17="04. UX Design")),IF(AND($H17<>"",$H17<=EOMONTH(N$12,0),$I17>=N$12),"UX+DEV","UX"),IF(AND($H17<>"",$H17<=EOMONTH(N$12,0),$I17>=N$12),"DEV","")))) | O17: =IF($AI17="","",IF(AND($AN17<>"",$AN17<=EOMONTH(O$12,0),$AO17>=O$12),IF(AND(INDEX('Roadmap Calc (Don’t Touch)'!$AA$2:$AX$151,$AI17,COLUMN()-COLUMN($J$16)+1)>0,OR($D17="03. UX Discovery",$D17="04. UX Design")),IF(AND($H17<>"",$H17<=EOMONTH(O$12,0),$I17>=O$12),"ALL","PD+UX"),IF(AND($H17<>"",$H17<=EOMONTH(O$12,0),$I17>=O$12),"PD+DEV","PD")),IF(AND(INDEX('Roadmap Calc (Don’t Touch)'!$AA$2:$AX$151,$AI17,COLUMN()-COLUMN($J$16)+1)>0,OR($D17="03. UX Discovery",$D17="04. UX Design")),IF(AND($H17<>"",$H17<=EOMONTH(O$12,0),$I17>=O$12),"UX+DEV","UX"),IF(AND($H17<>"",$H17<=EOMONTH(O$12,0),$I17>=O$12),"DEV","")))) | P17: =IF($AI17="","",IF(AND($AN17<>"",$AN17<=EOMONTH(P$12,0),$AO17>=P$12),IF(AND(INDEX('Roadmap Calc (Don’t Touch)'!$AA$2:$AX$151,$AI17,COLUMN()-COLUMN($J$16)+1)>0,OR($D17="03. UX Discovery",$D17="04. UX Design")),IF(AND($H17<>"",$H17<=EOMONTH(P$12,0),$I17>=P$12),"ALL","PD+UX"),IF(AND($H17<>"",$H17<=EOMONTH(P$12,0),$I17>=P$12),"PD+DEV","PD")),IF(AND(INDEX('Roadmap Calc (Don’t Touch)'!$AA$2:$AX$151,$AI17,COLUMN()-COLUMN($J$16)+1)>0,OR($D17="03. UX Discovery",$D17="04. UX Design")),IF(AND($H17<>"",$H17<=EOMONTH(P$12,0),$I17>=P$12),"UX+DEV","UX"),IF(AND($H17<>"",$H17<=EOMONTH(P$12,0),$I17>=P$12),"DEV","")))) | Q17: =IF($AI17="","",IF(AND($AN17<>"",$AN17<=EOMONTH(Q$12,0),$AO17>=Q$12),IF(AND(INDEX('Roadmap Calc (Don’t Touch)'!$AA$2:$AX$151,$AI17,COLUMN()-COLUMN($J$16)+1)>0,OR($D17="03. UX Discovery",$D17="04. UX Design")),IF(AND($H17<>"",$H17<=EOMONTH(Q$12,0),$I17>=Q$12),"ALL","PD+UX"),IF(AND($H17<>"",$H17<=EOMONTH(Q$12,0),$I17>=Q$12),"PD+DEV","PD")),IF(AND(INDEX('Roadmap Calc (Don’t Touch)'!$AA$2:$AX$151,$AI17,COLUMN()-COLUMN($J$16)+1)>0,OR($D17="03. UX Discovery",$D17="04. UX Design")),IF(AND($H17<>"",$H17<=EOMONTH(Q$12,0),$I17>=Q$12),"UX+DEV","UX"),IF(AND($H17<>"",$H17<=EOMONTH(Q$12,0),$I17>=Q$12),"DEV","")))) | ... AG17: =IF($AI17="","",IF(AND($AN17<>"",$AN17<=EOMONTH(AG$12,0),$AO17>=AG$12),IF(AND(INDEX('Roadmap Calc (Don’t Touch)'!$AA$2:$AX$151,$AI17,COLUMN()-COLUMN($J$16)+1)>0,OR($D17="03. UX Discovery",$D17="04. UX Design")),IF(AND($H17<>"",$H17<=EOMONTH(AG$12,0),$I17>=AG$12),"ALL","PD+UX"),IF(AND($H17<>"",$H17<=EOMONTH(AG$12,0),$I17>=AG$12),"PD+DEV","PD")),IF(AND(INDEX('Roadmap Calc (Don’t Touch)'!$AA$2:$AX$151,$AI17,COLUMN()-COLUMN($J$16)+1)>0,OR($D17="03. UX Discovery",$D17="04. UX Design")),IF(AND($H17<>"",$H17<=EOMONTH(AG$12,0),$I17>=AG$12),"UX+DEV","UX"),IF(AND($H17<>"",$H17<=EOMONTH(AG$12,0),$I17>=AG$12),"DEV","")))) | AH17: =IF($AI17="","",INDEX('Roadmap Calc (Don’t Touch)'!$D$2:$D$151,$AI17)) -> Increase Trade In Awareness | AI17: =IFERROR(MATCH(2,'Roadmap Calc (Don’t Touch)'!$O$2:$O$151,0),"") -> 8 | AK17: =IF(COUNTA(Control!E15)=0,"",Control!E15) -> Improve Search & Findability | AL17: =IF(COUNTA(Control!B15)=0,"",Control!B15) -> 09. In Dev | AN17: =IF($AI17="","",IF(ISNUMBER(INDEX('Roadmap Calc (Don’t Touch)'!$BB$2:$BB$151,$AI17)),INDEX('Roadmap Calc (Don’t Touch)'!$BB$2:$BB$151,$AI17),"")) | AO17: =IF($AI17="","",IF(ISNUMBER(INDEX('Roadmap Calc (Don’t Touch)'!$BC$2:$BC$151,$AI17)),INDEX('Roadmap Calc (Don’t Touch)'!$BC$2:$BC$151,$AI17),""))
A18: =IF($AI18="","",IF($AH18=$AH17,"",IF(INDEX('Roadmap Calc (Don’t Touch)'!$U$2:$U$151,$AI18)=0,$AH18,HYPERLINK("#'Control (Don’t Touch)'!E"&INDEX('Roadmap Calc (Don’t Touch)'!$U$2:$U$151,$AI18),$AH18)))) | B18: =IF($AI18="","",IF(INDEX('Roadmap Calc (Don’t Touch)'!$K$2:$K$151,$AI18)="",INDEX('Roadmap Calc (Don’t Touch)'!$B$2:$B$151,$AI18),HYPERLINK("https://jira.bnh.com/browse/"&INDEX('Roadmap Calc (Don’t Touch)'!$K$2:$K$151,$AI18),INDEX('Roadmap Calc (Don’t Touch)'!$B$2:$B$151,$AI18)))) -> Used Activity Notification | C18: =IF($AI18="","",IF(INDEX('Roadmap Calc (Don’t Touch)'!$E$2:$E$151,$AI18)="","",HYPERLINK("https://jira.bnh.com/browse/"&INDEX('Roadmap Calc (Don’t Touch)'!$E$2:$E$151,$AI18),INDEX('Roadmap Calc (Don’t Touch)'!$E$2:$E$151,$AI18)))) -> BHP-7237 | D18: =IF($AI18="","",INDEX('Roadmap Calc (Don’t Touch)'!$F$2:$F$151,$AI18)) -> 02. UX Req | E18: =IF($AI18="","",IF(ISNUMBER(INDEX('Roadmap Calc (Don’t Touch)'!$G$2:$G$151,$AI18)),INDEX('Roadmap Calc (Don’t Touch)'!$G$2:$G$151,$AI18),"")) -> 46279 | F18: =IF($AI18="","",IF(ISNUMBER(INDEX('Roadmap Calc (Don’t Touch)'!$H$2:$H$151,$AI18)),INDEX('Roadmap Calc (Don’t Touch)'!$H$2:$H$151,$AI18),"")) -> 46293 | G18: =IF($AI18="","",INDEX('Roadmap Calc (Don’t Touch)'!$T$2:$T$151,$AI18)) -> 3 | H18: =IF($AI18="","",IF(ISNUMBER(INDEX('Roadmap Calc (Don’t Touch)'!$I$2:$I$151,$AI18)),INDEX('Roadmap Calc (Don’t Touch)'!$I$2:$I$151,$AI18),"")) -> 46357 | I18: =IF($AI18="","",IF(ISNUMBER(INDEX('Roadmap Calc (Don’t Touch)'!$J$2:$J$151,$AI18)),INDEX('Roadmap Calc (Don’t Touch)'!$J$2:$J$151,$AI18),"")) -> 46418 | J18: =IF($AI18="","",IF(AND($AN18<>"",$AN18<=EOMONTH(J$12,0),$AO18>=J$12),IF(AND(INDEX('Roadmap Calc (Don’t Touch)'!$AA$2:$AX$151,$AI18,COLUMN()-COLUMN($J$16)+1)>0,OR($D18="03. UX Discovery",$D18="04. UX Design")),IF(AND($H18<>"",$H18<=EOMONTH(J$12,0),$I18>=J$12),"ALL","PD+UX"),IF(AND($H18<>"",$H18<=EOMONTH(J$12,0),$I18>=J$12),"PD+DEV","PD")),IF(AND(INDEX('Roadmap Calc (Don’t Touch)'!$AA$2:$AX$151,$AI18,COLUMN()-COLUMN($J$16)+1)>0,OR($D18="03. UX Discovery",$D18="04. UX Design")),IF(AND($H18<>"",$H18<=EOMONTH(J$12,0),$I18>=J$12),"UX+DEV","UX"),IF(AND($H18<>"",$H18<=EOMONTH(J$12,0),$I18>=J$12),"DEV","")))) | K18: =IF($AI18="","",IF(AND($AN18<>"",$AN18<=EOMONTH(K$12,0),$AO18>=K$12),IF(AND(INDEX('Roadmap Calc (Don’t Touch)'!$AA$2:$AX$151,$AI18,COLUMN()-COLUMN($J$16)+1)>0,OR($D18="03. UX Discovery",$D18="04. UX Design")),IF(AND($H18<>"",$H18<=EOMONTH(K$12,0),$I18>=K$12),"ALL","PD+UX"),IF(AND($H18<>"",$H18<=EOMONTH(K$12,0),$I18>=K$12),"PD+DEV","PD")),IF(AND(INDEX('Roadmap Calc (Don’t Touch)'!$AA$2:$AX$151,$AI18,COLUMN()-COLUMN($J$16)+1)>0,OR($D18="03. UX Discovery",$D18="04. UX Design")),IF(AND($H18<>"",$H18<=EOMONTH(K$12,0),$I18>=K$12),"UX+DEV","UX"),IF(AND($H18<>"",$H18<=EOMONTH(K$12,0),$I18>=K$12),"DEV","")))) | L18: =IF($AI18="","",IF(AND($AN18<>"",$AN18<=EOMONTH(L$12,0),$AO18>=L$12),IF(AND(INDEX('Roadmap Calc (Don’t Touch)'!$AA$2:$AX$151,$AI18,COLUMN()-COLUMN($J$16)+1)>0,OR($D18="03. UX Discovery",$D18="04. UX Design")),IF(AND($H18<>"",$H18<=EOMONTH(L$12,0),$I18>=L$12),"ALL","PD+UX"),IF(AND($H18<>"",$H18<=EOMONTH(L$12,0),$I18>=L$12),"PD+DEV","PD")),IF(AND(INDEX('Roadmap Calc (Don’t Touch)'!$AA$2:$AX$151,$AI18,COLUMN()-COLUMN($J$16)+1)>0,OR($D18="03. UX Discovery",$D18="04. UX Design")),IF(AND($H18<>"",$H18<=EOMONTH(L$12,0),$I18>=L$12),"UX+DEV","UX"),IF(AND($H18<>"",$H18<=EOMONTH(L$12,0),$I18>=L$12),"DEV","")))) | M18: =IF($AI18="","",IF(AND($AN18<>"",$AN18<=EOMONTH(M$12,0),$AO18>=M$12),IF(AND(INDEX('Roadmap Calc (Don’t Touch)'!$AA$2:$AX$151,$AI18,COLUMN()-COLUMN($J$16)+1)>0,OR($D18="03. UX Discovery",$D18="04. UX Design")),IF(AND($H18<>"",$H18<=EOMONTH(M$12,0),$I18>=M$12),"ALL","PD+UX"),IF(AND($H18<>"",$H18<=EOMONTH(M$12,0),$I18>=M$12),"PD+DEV","PD")),IF(AND(INDEX('Roadmap Calc (Don’t Touch)'!$AA$2:$AX$151,$AI18,COLUMN()-COLUMN($J$16)+1)>0,OR($D18="03. UX Discovery",$D18="04. UX Design")),IF(AND($H18<>"",$H18<=EOMONTH(M$12,0),$I18>=M$12),"UX+DEV","UX"),IF(AND($H18<>"",$H18<=EOMONTH(M$12,0),$I18>=M$12),"DEV","")))) | N18: =IF($AI18="","",IF(AND($AN18<>"",$AN18<=EOMONTH(N$12,0),$AO18>=N$12),IF(AND(INDEX('Roadmap Calc (Don’t Touch)'!$AA$2:$AX$151,$AI18,COLUMN()-COLUMN($J$16)+1)>0,OR($D18="03. UX Discovery",$D18="04. UX Design")),IF(AND($H18<>"",$H18<=EOMONTH(N$12,0),$I18>=N$12),"ALL","PD+UX"),IF(AND($H18<>"",$H18<=EOMONTH(N$12,0),$I18>=N$12),"PD+DEV","PD")),IF(AND(INDEX('Roadmap Calc (Don’t Touch)'!$AA$2:$AX$151,$AI18,COLUMN()-COLUMN($J$16)+1)>0,OR($D18="03. UX Discovery",$D18="04. UX Design")),IF(AND($H18<>"",$H18<=EOMONTH(N$12,0),$I18>=N$12),"UX+DEV","UX"),IF(AND($H18<>"",$H18<=EOMONTH(N$12,0),$I18>=N$12),"DEV","")))) | O18: =IF($AI18="","",IF(AND($AN18<>"",$AN18<=EOMONTH(O$12,0),$AO18>=O$12),IF(AND(INDEX('Roadmap Calc (Don’t Touch)'!$AA$2:$AX$151,$AI18,COLUMN()-COLUMN($J$16)+1)>0,OR($D18="03. UX Discovery",$D18="04. UX Design")),IF(AND($H18<>"",$H18<=EOMONTH(O$12,0),$I18>=O$12),"ALL","PD+UX"),IF(AND($H18<>"",$H18<=EOMONTH(O$12,0),$I18>=O$12),"PD+DEV","PD")),IF(AND(INDEX('Roadmap Calc (Don’t Touch)'!$AA$2:$AX$151,$AI18,COLUMN()-COLUMN($J$16)+1)>0,OR($D18="03. UX Discovery",$D18="04. UX Design")),IF(AND($H18<>"",$H18<=EOMONTH(O$12,0),$I18>=O$12),"UX+DEV","UX"),IF(AND($H18<>"",$H18<=EOMONTH(O$12,0),$I18>=O$12),"DEV","")))) | P18: =IF($AI18="","",IF(AND($AN18<>"",$AN18<=EOMONTH(P$12,0),$AO18>=P$12),IF(AND(INDEX('Roadmap Calc (Don’t Touch)'!$AA$2:$AX$151,$AI18,COLUMN()-COLUMN($J$16)+1)>0,OR($D18="03. UX Discovery",$D18="04. UX Design")),IF(AND($H18<>"",$H18<=EOMONTH(P$12,0),$I18>=P$12),"ALL","PD+UX"),IF(AND($H18<>"",$H18<=EOMONTH(P$12,0),$I18>=P$12),"PD+DEV","PD")),IF(AND(INDEX('Roadmap Calc (Don’t Touch)'!$AA$2:$AX$151,$AI18,COLUMN()-COLUMN($J$16)+1)>0,OR($D18="03. UX Discovery",$D18="04. UX Design")),IF(AND($H18<>"",$H18<=EOMONTH(P$12,0),$I18>=P$12),"UX+DEV","UX"),IF(AND($H18<>"",$H18<=EOMONTH(P$12,0),$I18>=P$12),"DEV","")))) | Q18: =IF($AI18="","",IF(AND($AN18<>"",$AN18<=EOMONTH(Q$12,0),$AO18>=Q$12),IF(AND(INDEX('Roadmap Calc (Don’t Touch)'!$AA$2:$AX$151,$AI18,COLUMN()-COLUMN($J$16)+1)>0,OR($D18="03. UX Discovery",$D18="04. UX Design")),IF(AND($H18<>"",$H18<=EOMONTH(Q$12,0),$I18>=Q$12),"ALL","PD+UX"),IF(AND($H18<>"",$H18<=EOMONTH(Q$12,0),$I18>=Q$12),"PD+DEV","PD")),IF(AND(INDEX('Roadmap Calc (Don’t Touch)'!$AA$2:$AX$151,$AI18,COLUMN()-COLUMN($J$16)+1)>0,OR($D18="03. UX Discovery",$D18="04. UX Design")),IF(AND($H18<>"",$H18<=EOMONTH(Q$12,0),$I18>=Q$12),"UX+DEV","UX"),IF(AND($H18<>"",$H18<=EOMONTH(Q$12,0),$I18>=Q$12),"DEV","")))) | ... AG18: =IF($AI18="","",IF(AND($AN18<>"",$AN18<=EOMONTH(AG$12,0),$AO18>=AG$12),IF(AND(INDEX('Roadmap Calc (Don’t Touch)'!$AA$2:$AX$151,$AI18,COLUMN()-COLUMN($J$16)+1)>0,OR($D18="03. UX Discovery",$D18="04. UX Design")),IF(AND($H18<>"",$H18<=EOMONTH(AG$12,0),$I18>=AG$12),"ALL","PD+UX"),IF(AND($H18<>"",$H18<=EOMONTH(AG$12,0),$I18>=AG$12),"PD+DEV","PD")),IF(AND(INDEX('Roadmap Calc (Don’t Touch)'!$AA$2:$AX$151,$AI18,COLUMN()-COLUMN($J$16)+1)>0,OR($D18="03. UX Discovery",$D18="04. UX Design")),IF(AND($H18<>"",$H18<=EOMONTH(AG$12,0),$I18>=AG$12),"UX+DEV","UX"),IF(AND($H18<>"",$H18<=EOMONTH(AG$12,0),$I18>=AG$12),"DEV","")))) | AH18: =IF($AI18="","",INDEX('Roadmap Calc (Don’t Touch)'!$D$2:$D$151,$AI18)) -> Increase Trade In Awareness | AI18: =IFERROR(MATCH(3,'Roadmap Calc (Don’t Touch)'!$O$2:$O$151,0),"") -> 11 | AK18: =IF(COUNTA(Control!E16)=0,"",Control!E16) | AL18: =IF(COUNTA(Control!B16)=0,"",Control!B16) -> 10. QA | AN18: =IF($AI18="","",IF(ISNUMBER(INDEX('Roadmap Calc (Don’t Touch)'!$BB$2:$BB$151,$AI18)),INDEX('Roadmap Calc (Don’t Touch)'!$BB$2:$BB$151,$AI18),"")) | AO18: =IF($AI18="","",IF(ISNUMBER(INDEX('Roadmap Calc (Don’t Touch)'!$BC$2:$BC$151,$AI18)),INDEX('Roadmap Calc (Don’t Touch)'!$BC$2:$BC$151,$AI18),""))
A19: =IF($AI19="","",IF($AH19=$AH18,"",IF(INDEX('Roadmap Calc (Don’t Touch)'!$U$2:$U$151,$AI19)=0,$AH19,HYPERLINK("#'Control (Don’t Touch)'!E"&INDEX('Roadmap Calc (Don’t Touch)'!$U$2:$U$151,$AI19),$AH19)))) | B19: =IF($AI19="","",IF(INDEX('Roadmap Calc (Don’t Touch)'!$K$2:$K$151,$AI19)="",INDEX('Roadmap Calc (Don’t Touch)'!$B$2:$B$151,$AI19),HYPERLINK("https://jira.bnh.com/browse/"&INDEX('Roadmap Calc (Don’t Touch)'!$K$2:$K$151,$AI19),INDEX('Roadmap Calc (Don’t Touch)'!$B$2:$B$151,$AI19)))) -> Increase Awareness of Trade In Offers - Best Buy Inspiration/Competitive Effort | C19: =IF($AI19="","",IF(INDEX('Roadmap Calc (Don’t Touch)'!$E$2:$E$151,$AI19)="","",HYPERLINK("https://jira.bnh.com/browse/"&INDEX('Roadmap Calc (Don’t Touch)'!$E$2:$E$151,$AI19),INDEX('Roadmap Calc (Don’t Touch)'!$E$2:$E$151,$AI19)))) -> BHP-6827 | D19: =IF($AI19="","",INDEX('Roadmap Calc (Don’t Touch)'!$F$2:$F$151,$AI19)) -> 03. UX Discovery | E19: =IF($AI19="","",IF(ISNUMBER(INDEX('Roadmap Calc (Don’t Touch)'!$G$2:$G$151,$AI19)),INDEX('Roadmap Calc (Don’t Touch)'!$G$2:$G$151,$AI19),"")) | F19: =IF($AI19="","",IF(ISNUMBER(INDEX('Roadmap Calc (Don’t Touch)'!$H$2:$H$151,$AI19)),INDEX('Roadmap Calc (Don’t Touch)'!$H$2:$H$151,$AI19),"")) | G19: =IF($AI19="","",INDEX('Roadmap Calc (Don’t Touch)'!$T$2:$T$151,$AI19)) -> 0 | H19: =IF($AI19="","",IF(ISNUMBER(INDEX('Roadmap Calc (Don’t Touch)'!$I$2:$I$151,$AI19)),INDEX('Roadmap Calc (Don’t Touch)'!$I$2:$I$151,$AI19),"")) -> 46296 | I19: =IF($AI19="","",IF(ISNUMBER(INDEX('Roadmap Calc (Don’t Touch)'!$J$2:$J$151,$AI19)),INDEX('Roadmap Calc (Don’t Touch)'!$J$2:$J$151,$AI19),"")) -> 46326 | J19: =IF($AI19="","",IF(AND($AN19<>"",$AN19<=EOMONTH(J$12,0),$AO19>=J$12),IF(AND(INDEX('Roadmap Calc (Don’t Touch)'!$AA$2:$AX$151,$AI19,COLUMN()-COLUMN($J$16)+1)>0,OR($D19="03. UX Discovery",$D19="04. UX Design")),IF(AND($H19<>"",$H19<=EOMONTH(J$12,0),$I19>=J$12),"ALL","PD+UX"),IF(AND($H19<>"",$H19<=EOMONTH(J$12,0),$I19>=J$12),"PD+DEV","PD")),IF(AND(INDEX('Roadmap Calc (Don’t Touch)'!$AA$2:$AX$151,$AI19,COLUMN()-COLUMN($J$16)+1)>0,OR($D19="03. UX Discovery",$D19="04. UX Design")),IF(AND($H19<>"",$H19<=EOMONTH(J$12,0),$I19>=J$12),"UX+DEV","UX"),IF(AND($H19<>"",$H19<=EOMONTH(J$12,0),$I19>=J$12),"DEV","")))) | K19: =IF($AI19="","",IF(AND($AN19<>"",$AN19<=EOMONTH(K$12,0),$AO19>=K$12),IF(AND(INDEX('Roadmap Calc (Don’t Touch)'!$AA$2:$AX$151,$AI19,COLUMN()-COLUMN($J$16)+1)>0,OR($D19="03. UX Discovery",$D19="04. UX Design")),IF(AND($H19<>"",$H19<=EOMONTH(K$12,0),$I19>=K$12),"ALL","PD+UX"),IF(AND($H19<>"",$H19<=EOMONTH(K$12,0),$I19>=K$12),"PD+DEV","PD")),IF(AND(INDEX('Roadmap Calc (Don’t Touch)'!$AA$2:$AX$151,$AI19,COLUMN()-COLUMN($J$16)+1)>0,OR($D19="03. UX Discovery",$D19="04. UX Design")),IF(AND($H19<>"",$H19<=EOMONTH(K$12,0),$I19>=K$12),"UX+DEV","UX"),IF(AND($H19<>"",$H19<=EOMONTH(K$12,0),$I19>=K$12),"DEV","")))) | L19: =IF($AI19="","",IF(AND($AN19<>"",$AN19<=EOMONTH(L$12,0),$AO19>=L$12),IF(AND(INDEX('Roadmap Calc (Don’t Touch)'!$AA$2:$AX$151,$AI19,COLUMN()-COLUMN($J$16)+1)>0,OR($D19="03. UX Discovery",$D19="04. UX Design")),IF(AND($H19<>"",$H19<=EOMONTH(L$12,0),$I19>=L$12),"ALL","PD+UX"),IF(AND($H19<>"",$H19<=EOMONTH(L$12,0),$I19>=L$12),"PD+DEV","PD")),IF(AND(INDEX('Roadmap Calc (Don’t Touch)'!$AA$2:$AX$151,$AI19,COLUMN()-COLUMN($J$16)+1)>0,OR($D19="03. UX Discovery",$D19="04. UX Design")),IF(AND($H19<>"",$H19<=EOMONTH(L$12,0),$I19>=L$12),"UX+DEV","UX"),IF(AND($H19<>"",$H19<=EOMONTH(L$12,0),$I19>=L$12),"DEV","")))) | M19: =IF($AI19="","",IF(AND($AN19<>"",$AN19<=EOMONTH(M$12,0),$AO19>=M$12),IF(AND(INDEX('Roadmap Calc (Don’t Touch)'!$AA$2:$AX$151,$AI19,COLUMN()-COLUMN($J$16)+1)>0,OR($D19="03. UX Discovery",$D19="04. UX Design")),IF(AND($H19<>"",$H19<=EOMONTH(M$12,0),$I19>=M$12),"ALL","PD+UX"),IF(AND($H19<>"",$H19<=EOMONTH(M$12,0),$I19>=M$12),"PD+DEV","PD")),IF(AND(INDEX('Roadmap Calc (Don’t Touch)'!$AA$2:$AX$151,$AI19,COLUMN()-COLUMN($J$16)+1)>0,OR($D19="03. UX Discovery",$D19="04. UX Design")),IF(AND($H19<>"",$H19<=EOMONTH(M$12,0),$I19>=M$12),"UX+DEV","UX"),IF(AND($H19<>"",$H19<=EOMONTH(M$12,0),$I19>=M$12),"DEV","")))) | N19: =IF($AI19="","",IF(AND($AN19<>"",$AN19<=EOMONTH(N$12,0),$AO19>=N$12),IF(AND(INDEX('Roadmap Calc (Don’t Touch)'!$AA$2:$AX$151,$AI19,COLUMN()-COLUMN($J$16)+1)>0,OR($D19="03. UX Discovery",$D19="04. UX Design")),IF(AND($H19<>"",$H19<=EOMONTH(N$12,0),$I19>=N$12),"ALL","PD+UX"),IF(AND($H19<>"",$H19<=EOMONTH(N$12,0),$I19>=N$12),"PD+DEV","PD")),IF(AND(INDEX('Roadmap Calc (Don’t Touch)'!$AA$2:$AX$151,$AI19,COLUMN()-COLUMN($J$16)+1)>0,OR($D19="03. UX Discovery",$D19="04. UX Design")),IF(AND($H19<>"",$H19<=EOMONTH(N$12,0),$I19>=N$12),"UX+DEV","UX"),IF(AND($H19<>"",$H19<=EOMONTH(N$12,0),$I19>=N$12),"DEV","")))) | O19: =IF($AI19="","",IF(AND($AN19<>"",$AN19<=EOMONTH(O$12,0),$AO19>=O$12),IF(AND(INDEX('Roadmap Calc (Don’t Touch)'!$AA$2:$AX$151,$AI19,COLUMN()-COLUMN($J$16)+1)>0,OR($D19="03. UX Discovery",$D19="04. UX Design")),IF(AND($H19<>"",$H19<=EOMONTH(O$12,0),$I19>=O$12),"ALL","PD+UX"),IF(AND($H19<>"",$H19<=EOMONTH(O$12,0),$I19>=O$12),"PD+DEV","PD")),IF(AND(INDEX('Roadmap Calc (Don’t Touch)'!$AA$2:$AX$151,$AI19,COLUMN()-COLUMN($J$16)+1)>0,OR($D19="03. UX Discovery",$D19="04. UX Design")),IF(AND($H19<>"",$H19<=EOMONTH(O$12,0),$I19>=O$12),"UX+DEV","UX"),IF(AND($H19<>"",$H19<=EOMONTH(O$12,0),$I19>=O$12),"DEV","")))) | P19: =IF($AI19="","",IF(AND($AN19<>"",$AN19<=EOMONTH(P$12,0),$AO19>=P$12),IF(AND(INDEX('Roadmap Calc (Don’t Touch)'!$AA$2:$AX$151,$AI19,COLUMN()-COLUMN($J$16)+1)>0,OR($D19="03. UX Discovery",$D19="04. UX Design")),IF(AND($H19<>"",$H19<=EOMONTH(P$12,0),$I19>=P$12),"ALL","PD+UX"),IF(AND($H19<>"",$H19<=EOMONTH(P$12,0),$I19>=P$12),"PD+DEV","PD")),IF(AND(INDEX('Roadmap Calc (Don’t Touch)'!$AA$2:$AX$151,$AI19,COLUMN()-COLUMN($J$16)+1)>0,OR($D19="03. UX Discovery",$D19="04. UX Design")),IF(AND($H19<>"",$H19<=EOMONTH(P$12,0),$I19>=P$12),"UX+DEV","UX"),IF(AND($H19<>"",$H19<=EOMONTH(P$12,0),$I19>=P$12),"DEV","")))) | Q19: =IF($AI19="","",IF(AND($AN19<>"",$AN19<=EOMONTH(Q$12,0),$AO19>=Q$12),IF(AND(INDEX('Roadmap Calc (Don’t Touch)'!$AA$2:$AX$151,$AI19,COLUMN()-COLUMN($J$16)+1)>0,OR($D19="03. UX Discovery",$D19="04. UX Design")),IF(AND($H19<>"",$H19<=EOMONTH(Q$12,0),$I19>=Q$12),"ALL","PD+UX"),IF(AND($H19<>"",$H19<=EOMONTH(Q$12,0),$I19>=Q$12),"PD+DEV","PD")),IF(AND(INDEX('Roadmap Calc (Don’t Touch)'!$AA$2:$AX$151,$AI19,COLUMN()-COLUMN($J$16)+1)>0,OR($D19="03. UX Discovery",$D19="04. UX Design")),IF(AND($H19<>"",$H19<=EOMONTH(Q$12,0),$I19>=Q$12),"UX+DEV","UX"),IF(AND($H19<>"",$H19<=EOMONTH(Q$12,0),$I19>=Q$12),"DEV","")))) | ... AG19: =IF($AI19="","",IF(AND($AN19<>"",$AN19<=EOMONTH(AG$12,0),$AO19>=AG$12),IF(AND(INDEX('Roadmap Calc (Don’t Touch)'!$AA$2:$AX$151,$AI19,COLUMN()-COLUMN($J$16)+1)>0,OR($D19="03. UX Discovery",$D19="04. UX Design")),IF(AND($H19<>"",$H19<=EOMONTH(AG$12,0),$I19>=AG$12),"ALL","PD+UX"),IF(AND($H19<>"",$H19<=EOMONTH(AG$12,0),$I19>=AG$12),"PD+DEV","PD")),IF(AND(INDEX('Roadmap Calc (Don’t Touch)'!$AA$2:$AX$151,$AI19,COLUMN()-COLUMN($J$16)+1)>0,OR($D19="03. UX Discovery",$D19="04. UX Design")),IF(AND($H19<>"",$H19<=EOMONTH(AG$12,0),$I19>=AG$12),"UX+DEV","UX"),IF(AND($H19<>"",$H19<=EOMONTH(AG$12,0),$I19>=AG$12),"DEV","")))) | AH19: =IF($AI19="","",INDEX('Roadmap Calc (Don’t Touch)'!$D$2:$D$151,$AI19)) -> Increase Trade In Awareness | AI19: =IFERROR(MATCH(4,'Roadmap Calc (Don’t Touch)'!$O$2:$O$151,0),"") -> 15 | AK19: =IF(COUNTA(Control!E17)=0,"",Control!E17) | AL19: =IF(COUNTA(Control!B17)=0,"",Control!B17) -> 11. UAT | AN19: =IF($AI19="","",IF(ISNUMBER(INDEX('Roadmap Calc (Don’t Touch)'!$BB$2:$BB$151,$AI19)),INDEX('Roadmap Calc (Don’t Touch)'!$BB$2:$BB$151,$AI19),"")) | AO19: =IF($AI19="","",IF(ISNUMBER(INDEX('Roadmap Calc (Don’t Touch)'!$BC$2:$BC$151,$AI19)),INDEX('Roadmap Calc (Don’t Touch)'!$BC$2:$BC$151,$AI19),""))
A20: =IF($AI20="","",IF($AH20=$AH19,"",IF(INDEX('Roadmap Calc (Don’t Touch)'!$U$2:$U$151,$AI20)=0,$AH20,HYPERLINK("#'Control (Don’t Touch)'!E"&INDEX('Roadmap Calc (Don’t Touch)'!$U$2:$U$151,$AI20),$AH20)))) | B20: =IF($AI20="","",IF(INDEX('Roadmap Calc (Don’t Touch)'!$K$2:$K$151,$AI20)="",INDEX('Roadmap Calc (Don’t Touch)'!$B$2:$B$151,$AI20),HYPERLINK("https://jira.bnh.com/browse/"&INDEX('Roadmap Calc (Don’t Touch)'!$K$2:$K$151,$AI20),INDEX('Roadmap Calc (Don’t Touch)'!$B$2:$B$151,$AI20)))) -> B2B & Used Visibility in the Nav | C20: =IF($AI20="","",IF(INDEX('Roadmap Calc (Don’t Touch)'!$E$2:$E$151,$AI20)="","",HYPERLINK("https://jira.bnh.com/browse/"&INDEX('Roadmap Calc (Don’t Touch)'!$E$2:$E$151,$AI20),INDEX('Roadmap Calc (Don’t Touch)'!$E$2:$E$151,$AI20)))) -> BHUX-34378 | D20: =IF($AI20="","",INDEX('Roadmap Calc (Don’t Touch)'!$F$2:$F$151,$AI20)) -> 04. UX Design | E20: =IF($AI20="","",IF(ISNUMBER(INDEX('Roadmap Calc (Don’t Touch)'!$G$2:$G$151,$AI20)),INDEX('Roadmap Calc (Don’t Touch)'!$G$2:$G$151,$AI20),"")) -> 46174 | F20: =IF($AI20="","",IF(ISNUMBER(INDEX('Roadmap Calc (Don’t Touch)'!$H$2:$H$151,$AI20)),INDEX('Roadmap Calc (Don’t Touch)'!$H$2:$H$151,$AI20),"")) -> 46293 | G20: =IF($AI20="","",INDEX('Roadmap Calc (Don’t Touch)'!$T$2:$T$151,$AI20)) -> 18 | H20: =IF($AI20="","",IF(ISNUMBER(INDEX('Roadmap Calc (Don’t Touch)'!$I$2:$I$151,$AI20)),INDEX('Roadmap Calc (Don’t Touch)'!$I$2:$I$151,$AI20),"")) -> 46419 | I20: =IF($AI20="","",IF(ISNUMBER(INDEX('Roadmap Calc (Don’t Touch)'!$J$2:$J$151,$AI20)),INDEX('Roadmap Calc (Don’t Touch)'!$J$2:$J$151,$AI20),"")) -> 46446 | J20: =IF($AI20="","",IF(AND($AN20<>"",$AN20<=EOMONTH(J$12,0),$AO20>=J$12),IF(AND(INDEX('Roadmap Calc (Don’t Touch)'!$AA$2:$AX$151,$AI20,COLUMN()-COLUMN($J$16)+1)>0,OR($D20="03. UX Discovery",$D20="04. UX Design")),IF(AND($H20<>"",$H20<=EOMONTH(J$12,0),$I20>=J$12),"ALL","PD+UX"),IF(AND($H20<>"",$H20<=EOMONTH(J$12,0),$I20>=J$12),"PD+DEV","PD")),IF(AND(INDEX('Roadmap Calc (Don’t Touch)'!$AA$2:$AX$151,$AI20,COLUMN()-COLUMN($J$16)+1)>0,OR($D20="03. UX Discovery",$D20="04. UX Design")),IF(AND($H20<>"",$H20<=EOMONTH(J$12,0),$I20>=J$12),"UX+DEV","UX"),IF(AND($H20<>"",$H20<=EOMONTH(J$12,0),$I20>=J$12),"DEV","")))) | K20: =IF($AI20="","",IF(AND($AN20<>"",$AN20<=EOMONTH(K$12,0),$AO20>=K$12),IF(AND(INDEX('Roadmap Calc (Don’t Touch)'!$AA$2:$AX$151,$AI20,COLUMN()-COLUMN($J$16)+1)>0,OR($D20="03. UX Discovery",$D20="04. UX Design")),IF(AND($H20<>"",$H20<=EOMONTH(K$12,0),$I20>=K$12),"ALL","PD+UX"),IF(AND($H20<>"",$H20<=EOMONTH(K$12,0),$I20>=K$12),"PD+DEV","PD")),IF(AND(INDEX('Roadmap Calc (Don’t Touch)'!$AA$2:$AX$151,$AI20,COLUMN()-COLUMN($J$16)+1)>0,OR($D20="03. UX Discovery",$D20="04. UX Design")),IF(AND($H20<>"",$H20<=EOMONTH(K$12,0),$I20>=K$12),"UX+DEV","UX"),IF(AND($H20<>"",$H20<=EOMONTH(K$12,0),$I20>=K$12),"DEV","")))) | L20: =IF($AI20="","",IF(AND($AN20<>"",$AN20<=EOMONTH(L$12,0),$AO20>=L$12),IF(AND(INDEX('Roadmap Calc (Don’t Touch)'!$AA$2:$AX$151,$AI20,COLUMN()-COLUMN($J$16)+1)>0,OR($D20="03. UX Discovery",$D20="04. UX Design")),IF(AND($H20<>"",$H20<=EOMONTH(L$12,0),$I20>=L$12),"ALL","PD+UX"),IF(AND($H20<>"",$H20<=EOMONTH(L$12,0),$I20>=L$12),"PD+DEV","PD")),IF(AND(INDEX('Roadmap Calc (Don’t Touch)'!$AA$2:$AX$151,$AI20,COLUMN()-COLUMN($J$16)+1)>0,OR($D20="03. UX Discovery",$D20="04. UX Design")),IF(AND($H20<>"",$H20<=EOMONTH(L$12,0),$I20>=L$12),"UX+DEV","UX"),IF(AND($H20<>"",$H20<=EOMONTH(L$12,0),$I20>=L$12),"DEV","")))) | M20: =IF($AI20="","",IF(AND($AN20<>"",$AN20<=EOMONTH(M$12,0),$AO20>=M$12),IF(AND(INDEX('Roadmap Calc (Don’t Touch)'!$AA$2:$AX$151,$AI20,COLUMN()-COLUMN($J$16)+1)>0,OR($D20="03. UX Discovery",$D20="04. UX Design")),IF(AND($H20<>"",$H20<=EOMONTH(M$12,0),$I20>=M$12),"ALL","PD+UX"),IF(AND($H20<>"",$H20<=EOMONTH(M$12,0),$I20>=M$12),"PD+DEV","PD")),IF(AND(INDEX('Roadmap Calc (Don’t Touch)'!$AA$2:$AX$151,$AI20,COLUMN()-COLUMN($J$16)+1)>0,OR($D20="03. UX Discovery",$D20="04. UX Design")),IF(AND($H20<>"",$H20<=EOMONTH(M$12,0),$I20>=M$12),"UX+DEV","UX"),IF(AND($H20<>"",$H20<=EOMONTH(M$12,0),$I20>=M$12),"DEV","")))) | N20: =IF($AI20="","",IF(AND($AN20<>"",$AN20<=EOMONTH(N$12,0),$AO20>=N$12),IF(AND(INDEX('Roadmap Calc (Don’t Touch)'!$AA$2:$AX$151,$AI20,COLUMN()-COLUMN($J$16)+1)>0,OR($D20="03. UX Discovery",$D20="04. UX Design")),IF(AND($H20<>"",$H20<=EOMONTH(N$12,0),$I20>=N$12),"ALL","PD+UX"),IF(AND($H20<>"",$H20<=EOMONTH(N$12,0),$I20>=N$12),"PD+DEV","PD")),IF(AND(INDEX('Roadmap Calc (Don’t Touch)'!$AA$2:$AX$151,$AI20,COLUMN()-COLUMN($J$16)+1)>0,OR($D20="03. UX Discovery",$D20="04. UX Design")),IF(AND($H20<>"",$H20<=EOMONTH(N$12,0),$I20>=N$12),"UX+DEV","UX"),IF(AND($H20<>"",$H20<=EOMONTH(N$12,0),$I20>=N$12),"DEV","")))) | O20: =IF($AI20="","",IF(AND($AN20<>"",$AN20<=EOMONTH(O$12,0),$AO20>=O$12),IF(AND(INDEX('Roadmap Calc (Don’t Touch)'!$AA$2:$AX$151,$AI20,COLUMN()-COLUMN($J$16)+1)>0,OR($D20="03. UX Discovery",$D20="04. UX Design")),IF(AND($H20<>"",$H20<=EOMONTH(O$12,0),$I20>=O$12),"ALL","PD+UX"),IF(AND($H20<>"",$H20<=EOMONTH(O$12,0),$I20>=O$12),"PD+DEV","PD")),IF(AND(INDEX('Roadmap Calc (Don’t Touch)'!$AA$2:$AX$151,$AI20,COLUMN()-COLUMN($J$16)+1)>0,OR($D20="03. UX Discovery",$D20="04. UX Design")),IF(AND($H20<>"",$H20<=EOMONTH(O$12,0),$I20>=O$12),"UX+DEV","UX"),IF(AND($H20<>"",$H20<=EOMONTH(O$12,0),$I20>=O$12),"DEV","")))) | P20: =IF($AI20="","",IF(AND($AN20<>"",$AN20<=EOMONTH(P$12,0),$AO20>=P$12),IF(AND(INDEX('Roadmap Calc (Don’t Touch)'!$AA$2:$AX$151,$AI20,COLUMN()-COLUMN($J$16)+1)>0,OR($D20="03. UX Discovery",$D20="04. UX Design")),IF(AND($H20<>"",$H20<=EOMONTH(P$12,0),$I20>=P$12),"ALL","PD+UX"),IF(AND($H20<>"",$H20<=EOMONTH(P$12,0),$I20>=P$12),"PD+DEV","PD")),IF(AND(INDEX('Roadmap Calc (Don’t Touch)'!$AA$2:$AX$151,$AI20,COLUMN()-COLUMN($J$16)+1)>0,OR($D20="03. UX Discovery",$D20="04. UX Design")),IF(AND($H20<>"",$H20<=EOMONTH(P$12,0),$I20>=P$12),"UX+DEV","UX"),IF(AND($H20<>"",$H20<=EOMONTH(P$12,0),$I20>=P$12),"DEV","")))) | Q20: =IF($AI20="","",IF(AND($AN20<>"",$AN20<=EOMONTH(Q$12,0),$AO20>=Q$12),IF(AND(INDEX('Roadmap Calc (Don’t Touch)'!$AA$2:$AX$151,$AI20,COLUMN()-COLUMN($J$16)+1)>0,OR($D20="03. UX Discovery",$D20="04. UX Design")),IF(AND($H20<>"",$H20<=EOMONTH(Q$12,0),$I20>=Q$12),"ALL","PD+UX"),IF(AND($H20<>"",$H20<=EOMONTH(Q$12,0),$I20>=Q$12),"PD+DEV","PD")),IF(AND(INDEX('Roadmap Calc (Don’t Touch)'!$AA$2:$AX$151,$AI20,COLUMN()-COLUMN($J$16)+1)>0,OR($D20="03. UX Discovery",$D20="04. UX Design")),IF(AND($H20<>"",$H20<=EOMONTH(Q$12,0),$I20>=Q$12),"UX+DEV","UX"),IF(AND($H20<>"",$H20<=EOMONTH(Q$12,0),$I20>=Q$12),"DEV","")))) | ... AG20: =IF($AI20="","",IF(AND($AN20<>"",$AN20<=EOMONTH(AG$12,0),$AO20>=AG$12),IF(AND(INDEX('Roadmap Calc (Don’t Touch)'!$AA$2:$AX$151,$AI20,COLUMN()-COLUMN($J$16)+1)>0,OR($D20="03. UX Discovery",$D20="04. UX Design")),IF(AND($H20<>"",$H20<=EOMONTH(AG$12,0),$I20>=AG$12),"ALL","PD+UX"),IF(AND($H20<>"",$H20<=EOMONTH(AG$12,0),$I20>=AG$12),"PD+DEV","PD")),IF(AND(INDEX('Roadmap Calc (Don’t Touch)'!$AA$2:$AX$151,$AI20,COLUMN()-COLUMN($J$16)+1)>0,OR($D20="03. UX Discovery",$D20="04. UX Design")),IF(AND($H20<>"",$H20<=EOMONTH(AG$12,0),$I20>=AG$12),"UX+DEV","UX"),IF(AND($H20<>"",$H20<=EOMONTH(AG$12,0),$I20>=AG$12),"DEV","")))) | AH20: =IF($AI20="","",INDEX('Roadmap Calc (Don’t Touch)'!$D$2:$D$151,$AI20)) -> Increase Trade In Awareness | AI20: =IFERROR(MATCH(5,'Roadmap Calc (Don’t Touch)'!$O$2:$O$151,0),"") -> 26 | AK20: =IF(COUNTA(Control!E18)=0,"",Control!E18) | AL20: =IF(COUNTA(Control!B18)=0,"",Control!B18) -> 12. Release | AN20: =IF($AI20="","",IF(ISNUMBER(INDEX('Roadmap Calc (Don’t Touch)'!$BB$2:$BB$151,$AI20)),INDEX('Roadmap Calc (Don’t Touch)'!$BB$2:$BB$151,$AI20),"")) | AO20: =IF($AI20="","",IF(ISNUMBER(INDEX('Roadmap Calc (Don’t Touch)'!$BC$2:$BC$151,$AI20)),INDEX('Roadmap Calc (Don’t Touch)'!$BC$2:$BC$151,$AI20),""))
A21: =IF($AI21="","",IF($AH21=$AH20,"",IF(INDEX('Roadmap Calc (Don’t Touch)'!$U$2:$U$151,$AI21)=0,$AH21,HYPERLINK("#'Control (Don’t Touch)'!E"&INDEX('Roadmap Calc (Don’t Touch)'!$U$2:$U$151,$AI21),$AH21)))) | B21: =IF($AI21="","",IF(INDEX('Roadmap Calc (Don’t Touch)'!$K$2:$K$151,$AI21)="",INDEX('Roadmap Calc (Don’t Touch)'!$B$2:$B$151,$AI21),HYPERLINK("https://jira.bnh.com/browse/"&INDEX('Roadmap Calc (Don’t Touch)'!$K$2:$K$151,$AI21),INDEX('Roadmap Calc (Don’t Touch)'!$B$2:$B$151,$AI21)))) -> PDP Purchased in 20XX, Trade In Value is $YYY.YY | C21: =IF($AI21="","",IF(INDEX('Roadmap Calc (Don’t Touch)'!$E$2:$E$151,$AI21)="","",HYPERLINK("https://jira.bnh.com/browse/"&INDEX('Roadmap Calc (Don’t Touch)'!$E$2:$E$151,$AI21),INDEX('Roadmap Calc (Don’t Touch)'!$E$2:$E$151,$AI21)))) -> BHUX-35309 | D21: =IF($AI21="","",INDEX('Roadmap Calc (Don’t Touch)'!$F$2:$F$151,$AI21)) -> 06. Architecture | E21: =IF($AI21="","",IF(ISNUMBER(INDEX('Roadmap Calc (Don’t Touch)'!$G$2:$G$151,$AI21)),INDEX('Roadmap Calc (Don’t Touch)'!$G$2:$G$151,$AI21),"")) -> 46251 | F21: =IF($AI21="","",IF(ISNUMBER(INDEX('Roadmap Calc (Don’t Touch)'!$H$2:$H$151,$AI21)),INDEX('Roadmap Calc (Don’t Touch)'!$H$2:$H$151,$AI21),"")) -> 46251 | G21: =IF($AI21="","",INDEX('Roadmap Calc (Don’t Touch)'!$T$2:$T$151,$AI21)) -> 1 | H21: =IF($AI21="","",IF(ISNUMBER(INDEX('Roadmap Calc (Don’t Touch)'!$I$2:$I$151,$AI21)),INDEX('Roadmap Calc (Don’t Touch)'!$I$2:$I$151,$AI21),"")) -> 46296 | I21: =IF($AI21="","",IF(ISNUMBER(INDEX('Roadmap Calc (Don’t Touch)'!$J$2:$J$151,$AI21)),INDEX('Roadmap Calc (Don’t Touch)'!$J$2:$J$151,$AI21),"")) -> 46326 | J21: =IF($AI21="","",IF(AND($AN21<>"",$AN21<=EOMONTH(J$12,0),$AO21>=J$12),IF(AND(INDEX('Roadmap Calc (Don’t Touch)'!$AA$2:$AX$151,$AI21,COLUMN()-COLUMN($J$16)+1)>0,OR($D21="03. UX Discovery",$D21="04. UX Design")),IF(AND($H21<>"",$H21<=EOMONTH(J$12,0),$I21>=J$12),"ALL","PD+UX"),IF(AND($H21<>"",$H21<=EOMONTH(J$12,0),$I21>=J$12),"PD+DEV","PD")),IF(AND(INDEX('Roadmap Calc (Don’t Touch)'!$AA$2:$AX$151,$AI21,COLUMN()-COLUMN($J$16)+1)>0,OR($D21="03. UX Discovery",$D21="04. UX Design")),IF(AND($H21<>"",$H21<=EOMONTH(J$12,0),$I21>=J$12),"UX+DEV","UX"),IF(AND($H21<>"",$H21<=EOMONTH(J$12,0),$I21>=J$12),"DEV","")))) | K21: =IF($AI21="","",IF(AND($AN21<>"",$AN21<=EOMONTH(K$12,0),$AO21>=K$12),IF(AND(INDEX('Roadmap Calc (Don’t Touch)'!$AA$2:$AX$151,$AI21,COLUMN()-COLUMN($J$16)+1)>0,OR($D21="03. UX Discovery",$D21="04. UX Design")),IF(AND($H21<>"",$H21<=EOMONTH(K$12,0),$I21>=K$12),"ALL","PD+UX"),IF(AND($H21<>"",$H21<=EOMONTH(K$12,0),$I21>=K$12),"PD+DEV","PD")),IF(AND(INDEX('Roadmap Calc (Don’t Touch)'!$AA$2:$AX$151,$AI21,COLUMN()-COLUMN($J$16)+1)>0,OR($D21="03. UX Discovery",$D21="04. UX Design")),IF(AND($H21<>"",$H21<=EOMONTH(K$12,0),$I21>=K$12),"UX+DEV","UX"),IF(AND($H21<>"",$H21<=EOMONTH(K$12,0),$I21>=K$12),"DEV","")))) | L21: =IF($AI21="","",IF(AND($AN21<>"",$AN21<=EOMONTH(L$12,0),$AO21>=L$12),IF(AND(INDEX('Roadmap Calc (Don’t Touch)'!$AA$2:$AX$151,$AI21,COLUMN()-COLUMN($J$16)+1)>0,OR($D21="03. UX Discovery",$D21="04. UX Design")),IF(AND($H21<>"",$H21<=EOMONTH(L$12,0),$I21>=L$12),"ALL","PD+UX"),IF(AND($H21<>"",$H21<=EOMONTH(L$12,0),$I21>=L$12),"PD+DEV","PD")),IF(AND(INDEX('Roadmap Calc (Don’t Touch)'!$AA$2:$AX$151,$AI21,COLUMN()-COLUMN($J$16)+1)>0,OR($D21="03. UX Discovery",$D21="04. UX Design")),IF(AND($H21<>"",$H21<=EOMONTH(L$12,0),$I21>=L$12),"UX+DEV","UX"),IF(AND($H21<>"",$H21<=EOMONTH(L$12,0),$I21>=L$12),"DEV","")))) | M21: =IF($AI21="","",IF(AND($AN21<>"",$AN21<=EOMONTH(M$12,0),$AO21>=M$12),IF(AND(INDEX('Roadmap Calc (Don’t Touch)'!$AA$2:$AX$151,$AI21,COLUMN()-COLUMN($J$16)+1)>0,OR($D21="03. UX Discovery",$D21="04. UX Design")),IF(AND($H21<>"",$H21<=EOMONTH(M$12,0),$I21>=M$12),"ALL","PD+UX"),IF(AND($H21<>"",$H21<=EOMONTH(M$12,0),$I21>=M$12),"PD+DEV","PD")),IF(AND(INDEX('Roadmap Calc (Don’t Touch)'!$AA$2:$AX$151,$AI21,COLUMN()-COLUMN($J$16)+1)>0,OR($D21="03. UX Discovery",$D21="04. UX Design")),IF(AND($H21<>"",$H21<=EOMONTH(M$12,0),$I21>=M$12),"UX+DEV","UX"),IF(AND($H21<>"",$H21<=EOMONTH(M$12,0),$I21>=M$12),"DEV","")))) | N21: =IF($AI21="","",IF(AND($AN21<>"",$AN21<=EOMONTH(N$12,0),$AO21>=N$12),IF(AND(INDEX('Roadmap Calc (Don’t Touch)'!$AA$2:$AX$151,$AI21,COLUMN()-COLUMN($J$16)+1)>0,OR($D21="03. UX Discovery",$D21="04. UX Design")),IF(AND($H21<>"",$H21<=EOMONTH(N$12,0),$I21>=N$12),"ALL","PD+UX"),IF(AND($H21<>"",$H21<=EOMONTH(N$12,0),$I21>=N$12),"PD+DEV","PD")),IF(AND(INDEX('Roadmap Calc (Don’t Touch)'!$AA$2:$AX$151,$AI21,COLUMN()-COLUMN($J$16)+1)>0,OR($D21="03. UX Discovery",$D21="04. UX Design")),IF(AND($H21<>"",$H21<=EOMONTH(N$12,0),$I21>=N$12),"UX+DEV","UX"),IF(AND($H21<>"",$H21<=EOMONTH(N$12,0),$I21>=N$12),"DEV","")))) | O21: =IF($AI21="","",IF(AND($AN21<>"",$AN21<=EOMONTH(O$12,0),$AO21>=O$12),IF(AND(INDEX('Roadmap Calc (Don’t Touch)'!$AA$2:$AX$151,$AI21,COLUMN()-COLUMN($J$16)+1)>0,OR($D21="03. UX Discovery",$D21="04. UX Design")),IF(AND($H21<>"",$H21<=EOMONTH(O$12,0),$I21>=O$12),"ALL","PD+UX"),IF(AND($H21<>"",$H21<=EOMONTH(O$12,0),$I21>=O$12),"PD+DEV","PD")),IF(AND(INDEX('Roadmap Calc (Don’t Touch)'!$AA$2:$AX$151,$AI21,COLUMN()-COLUMN($J$16)+1)>0,OR($D21="03. UX Discovery",$D21="04. UX Design")),IF(AND($H21<>"",$H21<=EOMONTH(O$12,0),$I21>=O$12),"UX+DEV","UX"),IF(AND($H21<>"",$H21<=EOMONTH(O$12,0),$I21>=O$12),"DEV","")))) | P21: =IF($AI21="","",IF(AND($AN21<>"",$AN21<=EOMONTH(P$12,0),$AO21>=P$12),IF(AND(INDEX('Roadmap Calc (Don’t Touch)'!$AA$2:$AX$151,$AI21,COLUMN()-COLUMN($J$16)+1)>0,OR($D21="03. UX Discovery",$D21="04. UX Design")),IF(AND($H21<>"",$H21<=EOMONTH(P$12,0),$I21>=P$12),"ALL","PD+UX"),IF(AND($H21<>"",$H21<=EOMONTH(P$12,0),$I21>=P$12),"PD+DEV","PD")),IF(AND(INDEX('Roadmap Calc (Don’t Touch)'!$AA$2:$AX$151,$AI21,COLUMN()-COLUMN($J$16)+1)>0,OR($D21="03. UX Discovery",$D21="04. UX Design")),IF(AND($H21<>"",$H21<=EOMONTH(P$12,0),$I21>=P$12),"UX+DEV","UX"),IF(AND($H21<>"",$H21<=EOMONTH(P$12,0),$I21>=P$12),"DEV","")))) | Q21: =IF($AI21="","",IF(AND($AN21<>"",$AN21<=EOMONTH(Q$12,0),$AO21>=Q$12),IF(AND(INDEX('Roadmap Calc (Don’t Touch)'!$AA$2:$AX$151,$AI21,COLUMN()-COLUMN($J$16)+1)>0,OR($D21="03. UX Discovery",$D21="04. UX Design")),IF(AND($H21<>"",$H21<=EOMONTH(Q$12,0),$I21>=Q$12),"ALL","PD+UX"),IF(AND($H21<>"",$H21<=EOMONTH(Q$12,0),$I21>=Q$12),"PD+DEV","PD")),IF(AND(INDEX('Roadmap Calc (Don’t Touch)'!$AA$2:$AX$151,$AI21,COLUMN()-COLUMN($J$16)+1)>0,OR($D21="03. UX Discovery",$D21="04. UX Design")),IF(AND($H21<>"",$H21<=EOMONTH(Q$12,0),$I21>=Q$12),"UX+DEV","UX"),IF(AND($H21<>"",$H21<=EOMONTH(Q$12,0),$I21>=Q$12),"DEV","")))) | ... AG21: =IF($AI21="","",IF(AND($AN21<>"",$AN21<=EOMONTH(AG$12,0),$AO21>=AG$12),IF(AND(INDEX('Roadmap Calc (Don’t Touch)'!$AA$2:$AX$151,$AI21,COLUMN()-COLUMN($J$16)+1)>0,OR($D21="03. UX Discovery",$D21="04. UX Design")),IF(AND($H21<>"",$H21<=EOMONTH(AG$12,0),$I21>=AG$12),"ALL","PD+UX"),IF(AND($H21<>"",$H21<=EOMONTH(AG$12,0),$I21>=AG$12),"PD+DEV","PD")),IF(AND(INDEX('Roadmap Calc (Don’t Touch)'!$AA$2:$AX$151,$AI21,COLUMN()-COLUMN($J$16)+1)>0,OR($D21="03. UX Discovery",$D21="04. UX Design")),IF(AND($H21<>"",$H21<=EOMONTH(AG$12,0),$I21>=AG$12),"UX+DEV","UX"),IF(AND($H21<>"",$H21<=EOMONTH(AG$12,0),$I21>=AG$12),"DEV","")))) | AH21: =IF($AI21="","",INDEX('Roadmap Calc (Don’t Touch)'!$D$2:$D$151,$AI21)) -> Increase Trade In Awareness | AI21: =IFERROR(MATCH(6,'Roadmap Calc (Don’t Touch)'!$O$2:$O$151,0),"") -> 29 | AL21: =IF(COUNTA(Control!B19)=0,"",Control!B19) -> 13. Live | AN21: =IF($AI21="","",IF(ISNUMBER(INDEX('Roadmap Calc (Don’t Touch)'!$BB$2:$BB$151,$AI21)),INDEX('Roadmap Calc (Don’t Touch)'!$BB$2:$BB$151,$AI21),"")) | AO21: =IF($AI21="","",IF(ISNUMBER(INDEX('Roadmap Calc (Don’t Touch)'!$BC$2:$BC$151,$AI21)),INDEX('Roadmap Calc (Don’t Touch)'!$BC$2:$BC$151,$AI21),""))
A22: =IF($AI22="","",IF($AH22=$AH21,"",IF(INDEX('Roadmap Calc (Don’t Touch)'!$U$2:$U$151,$AI22)=0,$AH22,HYPERLINK("#'Control (Don’t Touch)'!E"&INDEX('Roadmap Calc (Don’t Touch)'!$U$2:$U$151,$AI22),$AH22)))) -> Improve Trade In User Flow | B22: =IF($AI22="","",IF(INDEX('Roadmap Calc (Don’t Touch)'!$K$2:$K$151,$AI22)="",INDEX('Roadmap Calc (Don’t Touch)'!$B$2:$B$151,$AI22),HYPERLINK("https://jira.bnh.com/browse/"&INDEX('Roadmap Calc (Don’t Touch)'!$K$2:$K$151,$AI22),INDEX('Roadmap Calc (Don’t Touch)'!$B$2:$B$151,$AI22)))) -> Sell Used Purchase Look Up | C22: =IF($AI22="","",IF(INDEX('Roadmap Calc (Don’t Touch)'!$E$2:$E$151,$AI22)="","",HYPERLINK("https://jira.bnh.com/browse/"&INDEX('Roadmap Calc (Don’t Touch)'!$E$2:$E$151,$AI22),INDEX('Roadmap Calc (Don’t Touch)'!$E$2:$E$151,$AI22)))) -> BHP-7236 | D22: =IF($AI22="","",INDEX('Roadmap Calc (Don’t Touch)'!$F$2:$F$151,$AI22)) -> 02. UX Req | E22: =IF($AI22="","",IF(ISNUMBER(INDEX('Roadmap Calc (Don’t Touch)'!$G$2:$G$151,$AI22)),INDEX('Roadmap Calc (Don’t Touch)'!$G$2:$G$151,$AI22),"")) -> 46258 | F22: =IF($AI22="","",IF(ISNUMBER(INDEX('Roadmap Calc (Don’t Touch)'!$H$2:$H$151,$AI22)),INDEX('Roadmap Calc (Don’t Touch)'!$H$2:$H$151,$AI22),"")) -> 46272 | G22: =IF($AI22="","",INDEX('Roadmap Calc (Don’t Touch)'!$T$2:$T$151,$AI22)) -> 3 | H22: =IF($AI22="","",IF(ISNUMBER(INDEX('Roadmap Calc (Don’t Touch)'!$I$2:$I$151,$AI22)),INDEX('Roadmap Calc (Don’t Touch)'!$I$2:$I$151,$AI22),"")) -> 46327 | I22: =IF($AI22="","",IF(ISNUMBER(INDEX('Roadmap Calc (Don’t Touch)'!$J$2:$J$151,$AI22)),INDEX('Roadmap Calc (Don’t Touch)'!$J$2:$J$151,$AI22),"")) -> 46418 | J22: =IF($AI22="","",IF(AND($AN22<>"",$AN22<=EOMONTH(J$12,0),$AO22>=J$12),IF(AND(INDEX('Roadmap Calc (Don’t Touch)'!$AA$2:$AX$151,$AI22,COLUMN()-COLUMN($J$16)+1)>0,OR($D22="03. UX Discovery",$D22="04. UX Design")),IF(AND($H22<>"",$H22<=EOMONTH(J$12,0),$I22>=J$12),"ALL","PD+UX"),IF(AND($H22<>"",$H22<=EOMONTH(J$12,0),$I22>=J$12),"PD+DEV","PD")),IF(AND(INDEX('Roadmap Calc (Don’t Touch)'!$AA$2:$AX$151,$AI22,COLUMN()-COLUMN($J$16)+1)>0,OR($D22="03. UX Discovery",$D22="04. UX Design")),IF(AND($H22<>"",$H22<=EOMONTH(J$12,0),$I22>=J$12),"UX+DEV","UX"),IF(AND($H22<>"",$H22<=EOMONTH(J$12,0),$I22>=J$12),"DEV","")))) | K22: =IF($AI22="","",IF(AND($AN22<>"",$AN22<=EOMONTH(K$12,0),$AO22>=K$12),IF(AND(INDEX('Roadmap Calc (Don’t Touch)'!$AA$2:$AX$151,$AI22,COLUMN()-COLUMN($J$16)+1)>0,OR($D22="03. UX Discovery",$D22="04. UX Design")),IF(AND($H22<>"",$H22<=EOMONTH(K$12,0),$I22>=K$12),"ALL","PD+UX"),IF(AND($H22<>"",$H22<=EOMONTH(K$12,0),$I22>=K$12),"PD+DEV","PD")),IF(AND(INDEX('Roadmap Calc (Don’t Touch)'!$AA$2:$AX$151,$AI22,COLUMN()-COLUMN($J$16)+1)>0,OR($D22="03. UX Discovery",$D22="04. UX Design")),IF(AND($H22<>"",$H22<=EOMONTH(K$12,0),$I22>=K$12),"UX+DEV","UX"),IF(AND($H22<>"",$H22<=EOMONTH(K$12,0),$I22>=K$12),"DEV","")))) | L22: =IF($AI22="","",IF(AND($AN22<>"",$AN22<=EOMONTH(L$12,0),$AO22>=L$12),IF(AND(INDEX('Roadmap Calc (Don’t Touch)'!$AA$2:$AX$151,$AI22,COLUMN()-COLUMN($J$16)+1)>0,OR($D22="03. UX Discovery",$D22="04. UX Design")),IF(AND($H22<>"",$H22<=EOMONTH(L$12,0),$I22>=L$12),"ALL","PD+UX"),IF(AND($H22<>"",$H22<=EOMONTH(L$12,0),$I22>=L$12),"PD+DEV","PD")),IF(AND(INDEX('Roadmap Calc (Don’t Touch)'!$AA$2:$AX$151,$AI22,COLUMN()-COLUMN($J$16)+1)>0,OR($D22="03. UX Discovery",$D22="04. UX Design")),IF(AND($H22<>"",$H22<=EOMONTH(L$12,0),$I22>=L$12),"UX+DEV","UX"),IF(AND($H22<>"",$H22<=EOMONTH(L$12,0),$I22>=L$12),"DEV","")))) | M22: =IF($AI22="","",IF(AND($AN22<>"",$AN22<=EOMONTH(M$12,0),$AO22>=M$12),IF(AND(INDEX('Roadmap Calc (Don’t Touch)'!$AA$2:$AX$151,$AI22,COLUMN()-COLUMN($J$16)+1)>0,OR($D22="03. UX Discovery",$D22="04. UX Design")),IF(AND($H22<>"",$H22<=EOMONTH(M$12,0),$I22>=M$12),"ALL","PD+UX"),IF(AND($H22<>"",$H22<=EOMONTH(M$12,0),$I22>=M$12),"PD+DEV","PD")),IF(AND(INDEX('Roadmap Calc (Don’t Touch)'!$AA$2:$AX$151,$AI22,COLUMN()-COLUMN($J$16)+1)>0,OR($D22="03. UX Discovery",$D22="04. UX Design")),IF(AND($H22<>"",$H22<=EOMONTH(M$12,0),$I22>=M$12),"UX+DEV","UX"),IF(AND($H22<>"",$H22<=EOMONTH(M$12,0),$I22>=M$12),"DEV","")))) | N22: =IF($AI22="","",IF(AND($AN22<>"",$AN22<=EOMONTH(N$12,0),$AO22>=N$12),IF(AND(INDEX('Roadmap Calc (Don’t Touch)'!$AA$2:$AX$151,$AI22,COLUMN()-COLUMN($J$16)+1)>0,OR($D22="03. UX Discovery",$D22="04. UX Design")),IF(AND($H22<>"",$H22<=EOMONTH(N$12,0),$I22>=N$12),"ALL","PD+UX"),IF(AND($H22<>"",$H22<=EOMONTH(N$12,0),$I22>=N$12),"PD+DEV","PD")),IF(AND(INDEX('Roadmap Calc (Don’t Touch)'!$AA$2:$AX$151,$AI22,COLUMN()-COLUMN($J$16)+1)>0,OR($D22="03. UX Discovery",$D22="04. UX Design")),IF(AND($H22<>"",$H22<=EOMONTH(N$12,0),$I22>=N$12),"UX+DEV","UX"),IF(AND($H22<>"",$H22<=EOMONTH(N$12,0),$I22>=N$12),"DEV","")))) | O22: =IF($AI22="","",IF(AND($AN22<>"",$AN22<=EOMONTH(O$12,0),$AO22>=O$12),IF(AND(INDEX('Roadmap Calc (Don’t Touch)'!$AA$2:$AX$151,$AI22,COLUMN()-COLUMN($J$16)+1)>0,OR($D22="03. UX Discovery",$D22="04. UX Design")),IF(AND($H22<>"",$H22<=EOMONTH(O$12,0),$I22>=O$12),"ALL","PD+UX"),IF(AND($H22<>"",$H22<=EOMONTH(O$12,0),$I22>=O$12),"PD+DEV","PD")),IF(AND(INDEX('Roadmap Calc (Don’t Touch)'!$AA$2:$AX$151,$AI22,COLUMN()-COLUMN($J$16)+1)>0,OR($D22="03. UX Discovery",$D22="04. UX Design")),IF(AND($H22<>"",$H22<=EOMONTH(O$12,0),$I22>=O$12),"UX+DEV","UX"),IF(AND($H22<>"",$H22<=EOMONTH(O$12,0),$I22>=O$12),"DEV","")))) | P22: =IF($AI22="","",IF(AND($AN22<>"",$AN22<=EOMONTH(P$12,0),$AO22>=P$12),IF(AND(INDEX('Roadmap Calc (Don’t Touch)'!$AA$2:$AX$151,$AI22,COLUMN()-COLUMN($J$16)+1)>0,OR($D22="03. UX Discovery",$D22="04. UX Design")),IF(AND($H22<>"",$H22<=EOMONTH(P$12,0),$I22>=P$12),"ALL","PD+UX"),IF(AND($H22<>"",$H22<=EOMONTH(P$12,0),$I22>=P$12),"PD+DEV","PD")),IF(AND(INDEX('Roadmap Calc (Don’t Touch)'!$AA$2:$AX$151,$AI22,COLUMN()-COLUMN($J$16)+1)>0,OR($D22="03. UX Discovery",$D22="04. UX Design")),IF(AND($H22<>"",$H22<=EOMONTH(P$12,0),$I22>=P$12),"UX+DEV","UX"),IF(AND($H22<>"",$H22<=EOMONTH(P$12,0),$I22>=P$12),"DEV","")))) | Q22: =IF($AI22="","",IF(AND($AN22<>"",$AN22<=EOMONTH(Q$12,0),$AO22>=Q$12),IF(AND(INDEX('Roadmap Calc (Don’t Touch)'!$AA$2:$AX$151,$AI22,COLUMN()-COLUMN($J$16)+1)>0,OR($D22="03. UX Discovery",$D22="04. UX Design")),IF(AND($H22<>"",$H22<=EOMONTH(Q$12,0),$I22>=Q$12),"ALL","PD+UX"),IF(AND($H22<>"",$H22<=EOMONTH(Q$12,0),$I22>=Q$12),"PD+DEV","PD")),IF(AND(INDEX('Roadmap Calc (Don’t Touch)'!$AA$2:$AX$151,$AI22,COLUMN()-COLUMN($J$16)+1)>0,OR($D22="03. UX Discovery",$D22="04. UX Design")),IF(AND($H22<>"",$H22<=EOMONTH(Q$12,0),$I22>=Q$12),"UX+DEV","UX"),IF(AND($H22<>"",$H22<=EOMONTH(Q$12,0),$I22>=Q$12),"DEV","")))) | ... AG22: =IF($AI22="","",IF(AND($AN22<>"",$AN22<=EOMONTH(AG$12,0),$AO22>=AG$12),IF(AND(INDEX('Roadmap Calc (Don’t Touch)'!$AA$2:$AX$151,$AI22,COLUMN()-COLUMN($J$16)+1)>0,OR($D22="03. UX Discovery",$D22="04. UX Design")),IF(AND($H22<>"",$H22<=EOMONTH(AG$12,0),$I22>=AG$12),"ALL","PD+UX"),IF(AND($H22<>"",$H22<=EOMONTH(AG$12,0),$I22>=AG$12),"PD+DEV","PD")),IF(AND(INDEX('Roadmap Calc (Don’t Touch)'!$AA$2:$AX$151,$AI22,COLUMN()-COLUMN($J$16)+1)>0,OR($D22="03. UX Discovery",$D22="04. UX Design")),IF(AND($H22<>"",$H22<=EOMONTH(AG$12,0),$I22>=AG$12),"UX+DEV","UX"),IF(AND($H22<>"",$H22<=EOMONTH(AG$12,0),$I22>=AG$12),"DEV","")))) | AH22: =IF($AI22="","",INDEX('Roadmap Calc (Don’t Touch)'!$D$2:$D$151,$AI22)) -> Improve Trade In User Flow | AI22: =IFERROR(MATCH(7,'Roadmap Calc (Don’t Touch)'!$O$2:$O$151,0),"") -> 10 | AL22: =IF(COUNTA(Control!B20)=0,"",Control!B20) | AN22: =IF($AI22="","",IF(ISNUMBER(INDEX('Roadmap Calc (Don’t Touch)'!$BB$2:$BB$151,$AI22)),INDEX('Roadmap Calc (Don’t Touch)'!$BB$2:$BB$151,$AI22),"")) | AO22: =IF($AI22="","",IF(ISNUMBER(INDEX('Roadmap Calc (Don’t Touch)'!$BC$2:$BC$151,$AI22)),INDEX('Roadmap Calc (Don’t Touch)'!$BC$2:$BC$151,$AI22),""))
